Workbook
Name システム開発事業部: '業務報告書・社内用（20日締）'!$CH$2:$CH$4
Name 外勤: '業務報告書・社内用（20日締）'!$CF$2:$CF$6
Name 設計開発部: '業務報告書・社内用（20日締）'!$CG$2:$CG$3

Sheet 業務報告書・社内用（20日締）
A1: 業務報告書 | BE1: 勤怠状況① | BF1: 有給休暇 | BG1: 直行 | BH1: 遅刻（電車遅延） | BI1: 遅刻 | BJ1: 欠勤 | BK1: 特別休暇 | BL1: 振替休日 | BM1: 振替予定休日出勤 | BN1: 休日出勤 | BP1: 勤怠状況② | BQ1: 直帰 | BR1: 早退 | CF1: 外勤 | CG1: 設計開発部 | CH1: 開発部
AM2: 部署名 | BV2: -8.8817842e-16 | CF2: 開発部 | CG2: 待機 | CH2: システム開発１課
F3: 年 | M3: 月分 | AM3: 課名 | BE3: 平日 | BF3: =AS9 -> 0.375 | BG3: =AW9 -> 0.73958333 | BH3: =BG3*24-BF3*24-BH4 -> 7.75 | CF3: 環境部 | CG3: 基幹システム開発 | CH3: システム開発２課
AM4: 氏名 | AZ4: ㊞ | BE4: 休憩 | BF4: =AS10 -> 0.5 | BG4: =AW10 -> 0.54166667 | BH4: =BA10/60 -> 1 | BJ4: 範囲 | CF4: 新基幹システム開発 | CH4: 受託開発室
A5: （ | B5: =IF($I$3=1,12,$I$3-1) -> 8 | E5: 月 | G5: 21 | J5: 日 | L5: ～ | O5: =$I$3 -> 9 | R5: 月 | T5: 20 | W5: 日 | Y5: ） | AM5: 社員№ | BE5: 休憩 | BF5: =AS11 -> 0.73958333 | BG5: =AW11 -> 0.75 | BH5: =BA11/60 -> 0.25 | BJ5: =CONCATENATE(IF($I$3=1,IF($B$5=1,$A$3,$A$3-1),$A$3),"/",$B$5,"/",$G$5) -> 2026/8/21 | BK5: =CONCATENATE($A$3,"/",$O$5,"/",$T$5) -> 2026/9/20 | CF5: 尼崎技術研修所
A6: 就業日 | E6: 始業時刻 | I6: 終業時刻 | M6: 休憩 | O6: 時間内 時間 | S6: 時間外 時間 | W6: 深夜時間 | AA6: 休日勤務 時間 | AE6: 備考 | AJ6: 勤怠状況 | AP6: 届 | AQ6: 就業時間 | BE6: 深夜 | BF6: 0.91666667 | BG6: 1.2083333 | BN6: =BF3 -> 0.375 | BO6: =BF4 -> 0.5 | BP6: =BG4 -> 0.54166667 | BQ6: =BF5 -> 0.73958333 | BR6: =BG3 -> 0.73958333 | BS6: =BF6 -> 0.91666667 | BT6: =BF7 -> 0.20833333 | CF6: 待機
BE7: 早朝 | BF7: 0.20833333 | BG7: =AS9 -> 0.375 | BN7: =BF4 -> 0.5 | BO7: =BG4 -> 0.54166667 | BP7: =BG3 -> 0.73958333 | BQ7: =BG5 -> 0.75 | BR7: =BF6 -> 0.91666667 | BS7: =BG6 -> 1.2083333 | BT7: =BG7 -> 0.375 | BX7: =$AW$27/60 -> 0.25 | CC7: =$AW$24/60 -> 0.25
A8: 日 | C8: 曜 | E8: 時 | G8: 分 | I8: 時 | K8: 分 | M8: 分 | O8: 時 | Q8: 分 | S8: 時 | U8: 分 | W8: 時 | Y8: 分 | AA8: 時 | AC8: 分 | BH8: 平日フラグ | BI8: 休日フラグ | BJ8: 振休予定出勤フラグ | BK8: 休日出勤フラグ | BL8: 始業時刻 | BM8: 終業時刻 | BN8: AM | BO8: 休憩 | BP8: PM | BQ8: 休憩 | BR8: 時間外 | BS8: 深夜 | BT8: 早朝 | BU8: 時間内 | BV8: 控除 | BW8: 早退チェック | BX8: 控除チェック | BY8: 時間外平日 | BZ8: 時間外平日深夜 | CA8: 時間外休日 | CB8: 休日深夜 | CC8: 時間外チェック | CD8: 直行・直帰チェック
A9: 21 | C9: 金 | M9: =IF(E9="","",IF((BO9+BQ9)=0,"",(BO9+BQ9)*60)) -> 60 | O9: =IF(E9<>"",IF(BU9<>0,BU9/24,""),"") -> 0.19791667 | S9: =IF(E9<>"",IF(BY9<>0,BY9/24,""),"") | W9: =IF(E9<>"",IF(BS9<>0,BS9/24,""),"") | AA9: =IF(E9<>"",IF(CA9<>0,CA9/24,""),"") | AP9: =IF(OR(AJ9<>"",AN9<>"",(BV9+BW9)<>0),IF(CD9=1,"","要"),IF(OR(S9<>"",W9<>"",AA9<>""),"申","")) -> 要 | AQ9: 平日 | AS9: 0.375 | AV9: ～ | AW9: 0.73958333 | BD9: =IF(ISERR(DAY(BG9)),1,IF(AND(DATEVALUE(BG9)>=DATEVALUE($BJ$5),DATEVALUE(BG9)<=DATEVALUE($BK$5)),0,1)) -> 0 | BE9: =IF($I$3=1,$A$3-1,$A$3) -> 2026 | BF9: =IF($I$3=1,12,IF($B$5=$O$5,IF($B$5<$I$3,$B$5,$B$5-1),$B$5)) -> 8 | BG9: =CONCATENATE(BE9,"/",BF9,"/",A9) -> 2026/8/21 | BH9: =IF(OR(COUNTIF(祝祭日!$A:$A,$BG9)>=1,OR(C9="土",C9="日",C9="",BD9=1)),0,1) -> 1 | BI9: =IF(OR(AJ9="有給休暇",AJ9="欠勤",AJ9="振替休日",AJ9="特別休暇"),1,0) -> 0 | BJ9: =IF(AJ9="振替予定休日出勤",1,0) -> 0 | BK9: =IF(AJ9="休日出勤",IF(C9="日",1,2),0) -> 0 | BL9: =IFERROR(IF(BI9=1,TIME(0,0,0),TIME(E9,G9,0)),TIME(0,0,0)) -> 0.5 | BM9: =IFERROR(IF(BI9=1,TIME(0,0,0),IF(E9>I9,TIME(I9,K9,0)+1,TIME(I9,K9,0))),TIME(0,0,0)) -> 0.73958333 | BN9: =TEXT(MAX(0,MIN($BM9,BN$7)-MAX($BL9,BN$6)),"h:mm")*24 -> 0 | BO9: =TEXT(MAX(0,MIN($BM9,BO$7)-MAX($BL9,BO$6)),"h:mm")*24 -> 1 | BP9: =TEXT(MAX(0,MIN($BM9,BP$7)-MAX($BL9,BP$6)),"h:mm")*24 -> 4.75 | BQ9: =TEXT(MAX(0,MIN($BM9,BQ$7)-MAX($BL9,BQ$6)),"h:mm")*24 -> 0 | BR9: =TEXT(MAX(0,MIN($BM9,BR$7)-MAX($BL9,BR$6)),"h:mm")*24-BQ9 -> 0 | BS9: =TEXT(MAX(0,MIN($BM9,BS$7)-MAX($BL9,BS$6)),"h:mm")*24 -> 0 | BT9: =TEXT(MAX(0,MIN($BM9,BT$7)-MAX($BL9,BT$6)),"h:mm")*24 -> 0 | BU9: =IF(OR(BH9=1,BJ9=1),BN9+BP9,0) -> 4.75 | BV9: =IF(BU9>0,IF(AJ9="遅刻（電車遅延）",0,$BH$3-BU9),0) -> 3 | BW9: =IF(AND(BU9>0,BV9=0),IF(MIN($BP$7,BM9)=BM9,($BP$7-BM9)*24,0),0) -> 0 | BX9: =MOD(ROUND(BV9+BW9,2),ROUND($BX$7,2)) -> 0 | BY9: =IF(OR(BH9=1,BJ9=1),BR9+BT9,IF(C9="日",0,BN9+BP9+BR9+BT9)) -> 0 | BZ9: =IF(OR(BH9=1,BJ9=1),BS9,0) -> 0 | CA9: =IF(AND(C9="日",BJ9=0),BN9+BP9+BR9+BT9,0) -> 0 | CB9: =IF(AND(C9="日",BJ9=0),BS9,0) -> 0 | CC9: =MOD(ROUND(BY9+BZ9+CA9+CB9,2),ROUND($CC$7,2)) -> 0 | CD9: =IF(OR(AND(AJ9="直行",AN9="直帰"),AND(AJ9="",AN9="直帰"),AND(AJ9="直行",AN9="")),1,0) -> 0
A10: 22 | C10: 土 | AP10: =IF(OR(AJ10<>"",AN10<>"",(BV10+BW10)<>0),IF(CD10=1,"","要"),IF(OR(S10<>"",W10<>"",AA10<>""),"申","")) | AQ10: 休憩 | AS10: 0.5 | AV10: ～ | AW10: 0.54166667 | AZ10: ・ | BA10: 60 | BB10: 分 | BD10: =IF(ISERR(DAY(BG10)),1,IF(AND(DATEVALUE(BG10)>=DATEVALUE($BJ$5),DATEVALUE(BG10)<=DATEVALUE($BK$5)),0,1)) -> 0 | BE10: =IF($I$3=1,$A$3-1,$A$3) -> 2026 | BF10: =IF($I$3=1,12,IF($B$5=$O$5,IF($B$5<$I$3,$B$5,$B$5-1),$B$5)) -> 8 | BG10: =CONCATENATE(BE10,"/",BF10,"/",A10) -> 2026/8/22 | BH10: =IF(OR(COUNTIF(祝祭日!$A:$A,$BG10)>=1,OR(C10="土",C10="日",C10="",BD10=1)),0,1) -> 0 | BI10: =IF(OR(AJ10="有給休暇",AJ10="欠勤",AJ10="振替休日",AJ10="特別休暇"),1,0) -> 0 | BJ10: =IF(AJ10="振替予定休日出勤",1,0) -> 0 | BK10: =IF(AJ10="休日出勤",IF(C10="日",1,2),0) -> 0 | BL10: =IFERROR(IF(BI10=1,TIME(0,0,0),TIME(E10,G10,0)),TIME(0,0,0)) -> 0 | BM10: =IFERROR(IF(BI10=1,TIME(0,0,0),IF(E10>I10,TIME(I10,K10,0)+1,TIME(I10,K10,0))),TIME(0,0,0)) -> 0 | BN10: =TEXT(MAX(0,MIN($BM10,BN$7)-MAX($BL10,BN$6)),"h:mm")*24 -> 0 | BO10: =TEXT(MAX(0,MIN($BM10,BO$7)-MAX($BL10,BO$6)),"h:mm")*24 -> 0 | BP10: =TEXT(MAX(0,MIN($BM10,BP$7)-MAX($BL10,BP$6)),"h:mm")*24 -> 0 | BQ10: =TEXT(MAX(0,MIN($BM10,BQ$7)-MAX($BL10,BQ$6)),"h:mm")*24 -> 0 | BR10: =TEXT(MAX(0,MIN($BM10,BR$7)-MAX($BL10,BR$6)),"h:mm")*24-BQ10 -> 0 | BS10: =TEXT(MAX(0,MIN($BM10,BS$7)-MAX($BL10,BS$6)),"h:mm")*24 -> 0 | BT10: =TEXT(MAX(0,MIN($BM10,BT$7)-MAX($BL10,BT$6)),"h:mm")*24 -> 0 | BU10: =IF(OR(BH10=1,BJ10=1),BN10+BP10,0) -> 0 | BV10: =IF(BU10>0,IF(AJ10="遅刻（電車遅延）",0,$BH$3-BU10),0) -> 0 | BW10: =IF(AND(BU10>0,BV10=0),IF(MIN($BP$7,BM10)=BM10,($BP$7-BM10)*24,0),0) -> 0 | BX10: =MOD(ROUND(BV10+BW10,2),ROUND($BX$7,2)) -> 0 | BY10: =IF(OR(BH10=1,BJ10=1),BR10+BT10,IF(C10="日",0,BN10+BP10+BR10+BT10)) -> 0 | BZ10: =IF(OR(BH10=1,BJ10=1),BS10,0) -> 0 | CA10: =IF(AND(C10="日",BJ10=0),BN10+BP10+BR10+BT10,0) -> 0 | CB10: =IF(AND(C10="日",BJ10=0),BS10,0) -> 0 | CC10: =MOD(ROUND(BY10+BZ10+CA10+CB10,2),ROUND($CC$7,2)) -> 0 | CD10: =IF(OR(AND(AJ10="直行",AN10="直帰"),AND(AJ10="",AN10="直帰"),AND(AJ10="直行",AN10="")),1,0) -> 0
A11: 23 | C11: 日 | AP11: =IF(OR(AJ11<>"",AN11<>"",(BV11+BW11)<>0),IF(CD11=1,"","要"),IF(OR(S11<>"",W11<>"",AA11<>""),"申","")) | AS11: 0.73958333 | AV11: ～ | AW11: 0.75 | AZ11: ・ | BA11: 15 | BB11: 分 | BD11: =IF(ISERR(DAY(BG11)),1,IF(AND(DATEVALUE(BG11)>=DATEVALUE($BJ$5),DATEVALUE(BG11)<=DATEVALUE($BK$5)),0,1)) -> 0 | BE11: =IF($I$3=1,$A$3-1,$A$3) -> 2026 | BF11: =IF($I$3=1,12,IF($B$5=$O$5,IF($B$5<$I$3,$B$5,$B$5-1),$B$5)) -> 8 | BG11: =CONCATENATE(BE11,"/",BF11,"/",A11) -> 2026/8/23 | BH11: =IF(OR(COUNTIF(祝祭日!$A:$A,$BG11)>=1,OR(C11="土",C11="日",C11="",BD11=1)),0,1) -> 0 | BI11: =IF(OR(AJ11="有給休暇",AJ11="欠勤",AJ11="振替休日",AJ11="特別休暇"),1,0) -> 0 | BJ11: =IF(AJ11="振替予定休日出勤",1,0) -> 0 | BK11: =IF(AJ11="休日出勤",IF(C11="日",1,2),0) -> 0 | BL11: =IFERROR(IF(BI11=1,TIME(0,0,0),TIME(E11,G11,0)),TIME(0,0,0)) -> 0 | BM11: =IFERROR(IF(BI11=1,TIME(0,0,0),IF(E11>I11,TIME(I11,K11,0)+1,TIME(I11,K11,0))),TIME(0,0,0)) -> 0 | BN11: =TEXT(MAX(0,MIN($BM11,BN$7)-MAX($BL11,BN$6)),"h:mm")*24 -> 0 | BO11: =TEXT(MAX(0,MIN($BM11,BO$7)-MAX($BL11,BO$6)),"h:mm")*24 -> 0 | BP11: =TEXT(MAX(0,MIN($BM11,BP$7)-MAX($BL11,BP$6)),"h:mm")*24 -> 0 | BQ11: =TEXT(MAX(0,MIN($BM11,BQ$7)-MAX($BL11,BQ$6)),"h:mm")*24 -> 0 | BR11: =TEXT(MAX(0,MIN($BM11,BR$7)-MAX($BL11,BR$6)),"h:mm")*24-BQ11 -> 0 | BS11: =TEXT(MAX(0,MIN($BM11,BS$7)-MAX($BL11,BS$6)),"h:mm")*24 -> 0 | BT11: =TEXT(MAX(0,MIN($BM11,BT$7)-MAX($BL11,BT$6)),"h:mm")*24 -> 0 | BU11: =IF(OR(BH11=1,BJ11=1),BN11+BP11,0) -> 0 | BV11: =IF(BU11>0,IF(AJ11="遅刻（電車遅延）",0,$BH$3-BU11),0) -> 0 | BW11: =IF(AND(BU11>0,BV11=0),IF(MIN($BP$7,BM11)=BM11,($BP$7-BM11)*24,0),0) -> 0 | BX11: =MOD(ROUND(BV11+BW11,2),ROUND($BX$7,2)) -> 0 | BY11: =IF(OR(BH11=1,BJ11=1),BR11+BT11,IF(C11="日",0,BN11+BP11+BR11+BT11)) -> 0 | BZ11: =IF(OR(BH11=1,BJ11=1),BS11,0) -> 0 | CA11: =IF(AND(C11="日",BJ11=0),BN11+BP11+BR11+BT11,0) -> 0 | CB11: =IF(AND(C11="日",BJ11=0),BS11,0) -> 0 | CC11: =MOD(ROUND(BY11+BZ11+CA11+CB11,2),ROUND($CC$7,2)) -> 0 | CD11: =IF(OR(AND(AJ11="直行",AN11="直帰"),AND(AJ11="",AN11="直帰"),AND(AJ11="直行",AN11="")),1,0) -> 0 | CK11: 火
A12: 24 | C12: 月 | M12: =IF(E12="","",IF((BO12+BQ12)=0,"",(BO12+BQ12)*60)) -> 60 | O12: =IF(E12<>"",IF(BU12<>0,BU12/24,""),"") -> 0.32291667 | S12: =IF(E12<>"",IF(BY12<>0,BY12/24,""),"") | W12: =IF(E12<>"",IF(BS12<>0,BS12/24,""),"") | AA12: =IF(E12<>"",IF(CA12<>0,CA12/24,""),"") | AP12: =IF(OR(AJ12<>"",AN12<>"",(BV12+BW12)<>0),IF(CD12=1,"","要"),IF(OR(S12<>"",W12<>"",AA12<>""),"申","")) | AV12: ～ | AZ12: ・ | BD12: =IF(ISERR(DAY(BG12)),1,IF(AND(DATEVALUE(BG12)>=DATEVALUE($BJ$5),DATEVALUE(BG12)<=DATEVALUE($BK$5)),0,1)) -> 0 | BE12: =IF($I$3=1,$A$3-1,$A$3) -> 2026 | BF12: =IF($I$3=1,12,IF($B$5=$O$5,IF($B$5<$I$3,$B$5,$B$5-1),$B$5)) -> 8 | BG12: =CONCATENATE(BE12,"/",BF12,"/",A12) -> 2026/8/24 | BH12: =IF(OR(COUNTIF(祝祭日!$A:$A,$BG12)>=1,OR(C12="土",C12="日",C12="",BD12=1)),0,1) -> 1 | BI12: =IF(OR(AJ12="有給休暇",AJ12="欠勤",AJ12="振替休日",AJ12="特別休暇"),1,0) -> 0 | BJ12: =IF(AJ12="振替予定休日出勤",1,0) -> 0 | BK12: =IF(AJ12="休日出勤",IF(C12="日",1,2),0) -> 0 | BL12: =IFERROR(IF(BI12=1,TIME(0,0,0),TIME(E12,G12,0)),TIME(0,0,0)) -> 0.375 | BM12: =IFERROR(IF(BI12=1,TIME(0,0,0),IF(E12>I12,TIME(I12,K12,0)+1,TIME(I12,K12,0))),TIME(0,0,0)) -> 0.73958333 | BN12: =TEXT(MAX(0,MIN($BM12,BN$7)-MAX($BL12,BN$6)),"h:mm")*24 -> 3 | BO12: =TEXT(MAX(0,MIN($BM12,BO$7)-MAX($BL12,BO$6)),"h:mm")*24 -> 1 | BP12: =TEXT(MAX(0,MIN($BM12,BP$7)-MAX($BL12,BP$6)),"h:mm")*24 -> 4.75 | BQ12: =TEXT(MAX(0,MIN($BM12,BQ$7)-MAX($BL12,BQ$6)),"h:mm")*24 -> 0 | BR12: =TEXT(MAX(0,MIN($BM12,BR$7)-MAX($BL12,BR$6)),"h:mm")*24-BQ12 -> 0 | BS12: =TEXT(MAX(0,MIN($BM12,BS$7)-MAX($BL12,BS$6)),"h:mm")*24 -> 0 | BT12: =TEXT(MAX(0,MIN($BM12,BT$7)-MAX($BL12,BT$6)),"h:mm")*24 -> 0 | BU12: =IF(OR(BH12=1,BJ12=1),BN12+BP12,0) -> 7.75 | BV12: =IF(BU12>0,IF(AJ12="遅刻（電車遅延）",0,$BH$3-BU12),0) -> 0 | BW12: =IF(AND(BU12>0,BV12=0),IF(MIN($BP$7,BM12)=BM12,($BP$7-BM12)*24,0),0) -> 0 | BX12: =MOD(ROUND(BV12+BW12,2),ROUND($BX$7,2)) -> 0 | BY12: =IF(OR(BH12=1,BJ12=1),BR12+BT12,IF(C12="日",0,BN12+BP12+BR12+BT12)) -> 0 | BZ12: =IF(OR(BH12=1,BJ12=1),BS12,0) -> 0 | CA12: =IF(AND(C12="日",BJ12=0),BN12+BP12+BR12+BT12,0) -> 0 | CB12: =IF(AND(C12="日",BJ12=0),BS12,0) -> 0 | CC12: =MOD(ROUND(BY12+BZ12+CA12+CB12,2),ROUND($CC$7,2)) -> 0 | CD12: =IF(OR(AND(AJ12="直行",AN12="直帰"),AND(AJ12="",AN12="直帰"),AND(AJ12="直行",AN12="")),1,0) -> 0 | CK12: 水
A13: 25 | C13: 火 | M13: =IF(E13="","",IF((BO13+BQ13)=0,"",(BO13+BQ13)*60)) -> 60 | O13: =IF(E13<>"",IF(BU13<>0,BU13/24,""),"") -> 0.32291667 | S13: =IF(E13<>"",IF(BY13<>0,BY13/24,""),"") | W13: =IF(E13<>"",IF(BS13<>0,BS13/24,""),"") | AA13: =IF(E13<>"",IF(CA13<>0,CA13/24,""),"") | AP13: =IF(OR(AJ13<>"",AN13<>"",(BV13+BW13)<>0),IF(CD13=1,"","要"),IF(OR(S13<>"",W13<>"",AA13<>""),"申","")) | AV13: ～ | AZ13: ・ | BD13: =IF(ISERR(DAY(BG13)),1,IF(AND(DATEVALUE(BG13)>=DATEVALUE($BJ$5),DATEVALUE(BG13)<=DATEVALUE($BK$5)),0,1)) -> 0 | BE13: =IF($I$3=1,$A$3-1,$A$3) -> 2026 | BF13: =IF($I$3=1,12,IF($B$5=$O$5,IF($B$5<$I$3,$B$5,$B$5-1),$B$5)) -> 8 | BG13: =CONCATENATE(BE13,"/",BF13,"/",A13) -> 2026/8/25 | BH13: =IF(OR(COUNTIF(祝祭日!$A:$A,$BG13)>=1,OR(C13="土",C13="日",C13="",BD13=1)),0,1) -> 1 | BI13: =IF(OR(AJ13="有給休暇",AJ13="欠勤",AJ13="振替休日",AJ13="特別休暇"),1,0) -> 0 | BJ13: =IF(AJ13="振替予定休日出勤",1,0) -> 0 | BK13: =IF(AJ13="休日出勤",IF(C13="日",1,2),0) -> 0 | BL13: =IFERROR(IF(BI13=1,TIME(0,0,0),TIME(E13,G13,0)),TIME(0,0,0)) -> 0.375 | BM13: =IFERROR(IF(BI13=1,TIME(0,0,0),IF(E13>I13,TIME(I13,K13,0)+1,TIME(I13,K13,0))),TIME(0,0,0)) -> 0.73958333 | BN13: =TEXT(MAX(0,MIN($BM13,BN$7)-MAX($BL13,BN$6)),"h:mm")*24 -> 3 | BO13: =TEXT(MAX(0,MIN($BM13,BO$7)-MAX($BL13,BO$6)),"h:mm")*24 -> 1 | BP13: =TEXT(MAX(0,MIN($BM13,BP$7)-MAX($BL13,BP$6)),"h:mm")*24 -> 4.75 | BQ13: =TEXT(MAX(0,MIN($BM13,BQ$7)-MAX($BL13,BQ$6)),"h:mm")*24 -> 0 | BR13: =TEXT(MAX(0,MIN($BM13,BR$7)-MAX($BL13,BR$6)),"h:mm")*24-BQ13 -> 0 | BS13: =TEXT(MAX(0,MIN($BM13,BS$7)-MAX($BL13,BS$6)),"h:mm")*24 -> 0 | BT13: =TEXT(MAX(0,MIN($BM13,BT$7)-MAX($BL13,BT$6)),"h:mm")*24 -> 0 | BU13: =IF(OR(BH13=1,BJ13=1),BN13+BP13,0) -> 7.75 | BV13: =IF(BU13>0,IF(AJ13="遅刻（電車遅延）",0,$BH$3-BU13),0) -> 0 | BW13: =IF(AND(BU13>0,BV13=0),IF(MIN($BP$7,BM13)=BM13,($BP$7-BM13)*24,0),0) -> 0 | BX13: =MOD(ROUND(BV13+BW13,2),ROUND($BX$7,2)) -> 0 | BY13: =IF(OR(BH13=1,BJ13=1),BR13+BT13,IF(C13="日",0,BN13+BP13+BR13+BT13)) -> 0 | BZ13: =IF(OR(BH13=1,BJ13=1),BS13,0) -> 0 | CA13: =IF(AND(C13="日",BJ13=0),BN13+BP13+BR13+BT13,0) -> 0 | CB13: =IF(AND(C13="日",BJ13=0),BS13,0) -> 0 | CC13: =MOD(ROUND(BY13+BZ13+CA13+CB13,2),ROUND($CC$7,2)) -> 0 | CD13: =IF(OR(AND(AJ13="直行",AN13="直帰"),AND(AJ13="",AN13="直帰"),AND(AJ13="直行",AN13="")),1,0) -> 0 | CK13: 木
A14: 26 | C14: 水 | M14: =IF(E14="","",IF((BO14+BQ14)=0,"",(BO14+BQ14)*60)) -> 75 | O14: =IF(E14<>"",IF(BU14<>0,BU14/24,""),"") -> 0.32291667 | S14: =IF(E14<>"",IF(BY14<>0,BY14/24,""),"") -> 0.020833333 | W14: =IF(E14<>"",IF(BS14<>0,BS14/24,""),"") | AA14: =IF(E14<>"",IF(CA14<>0,CA14/24,""),"") | AP14: =IF(OR(AJ14<>"",AN14<>"",(BV14+BW14)<>0),IF(CD14=1,"","要"),IF(OR(S14<>"",W14<>"",AA14<>""),"申","")) -> 申 | AV14: ～ | AZ14: ・ | BD14: =IF(ISERR(DAY(BG14)),1,IF(AND(DATEVALUE(BG14)>=DATEVALUE($BJ$5),DATEVALUE(BG14)<=DATEVALUE($BK$5)),0,1)) -> 0 | BE14: =IF($I$3=1,$A$3-1,$A$3) -> 2026 | BF14: =IF($I$3=1,12,IF($B$5=$O$5,IF($B$5<$I$3,$B$5,$B$5-1),$B$5)) -> 8 | BG14: =CONCATENATE(BE14,"/",BF14,"/",A14) -> 2026/8/26 | BH14: =IF(OR(COUNTIF(祝祭日!$A:$A,$BG14)>=1,OR(C14="土",C14="日",C14="",BD14=1)),0,1) -> 1 | BI14: =IF(OR(AJ14="有給休暇",AJ14="欠勤",AJ14="振替休日",AJ14="特別休暇"),1,0) -> 0 | BJ14: =IF(AJ14="振替予定休日出勤",1,0) -> 0 | BK14: =IF(AJ14="休日出勤",IF(C14="日",1,2),0) -> 0 | BL14: =IFERROR(IF(BI14=1,TIME(0,0,0),TIME(E14,G14,0)),TIME(0,0,0)) -> 0.375 | BM14: =IFERROR(IF(BI14=1,TIME(0,0,0),IF(E14>I14,TIME(I14,K14,0)+1,TIME(I14,K14,0))),TIME(0,0,0)) -> 0.77083333 | BN14: =TEXT(MAX(0,MIN($BM14,BN$7)-MAX($BL14,BN$6)),"h:mm")*24 -> 3 | BO14: =TEXT(MAX(0,MIN($BM14,BO$7)-MAX($BL14,BO$6)),"h:mm")*24 -> 1 | BP14: =TEXT(MAX(0,MIN($BM14,BP$7)-MAX($BL14,BP$6)),"h:mm")*24 -> 4.75 | BQ14: =TEXT(MAX(0,MIN($BM14,BQ$7)-MAX($BL14,BQ$6)),"h:mm")*24 -> 0.25 | BR14: =TEXT(MAX(0,MIN($BM14,BR$7)-MAX($BL14,BR$6)),"h:mm")*24-BQ14 -> 0.5 | BS14: =TEXT(MAX(0,MIN($BM14,BS$7)-MAX($BL14,BS$6)),"h:mm")*24 -> 0 | BT14: =TEXT(MAX(0,MIN($BM14,BT$7)-MAX($BL14,BT$6)),"h:mm")*24 -> 0 | BU14: =IF(OR(BH14=1,BJ14=1),BN14+BP14,0) -> 7.75 | BV14: =IF(BU14>0,IF(AJ14="遅刻（電車遅延）",0,$BH$3-BU14),0) -> 0 | BW14: =IF(AND(BU14>0,BV14=0),IF(MIN($BP$7,BM14)=BM14,($BP$7-BM14)*24,0),0) -> 0 | BX14: =MOD(ROUND(BV14+BW14,2),ROUND($BX$7,2)) -> 0 | BY14: =IF(OR(BH14=1,BJ14=1),BR14+BT14,IF(C14="日",0,BN14+BP14+BR14+BT14)) -> 0.5 | BZ14: =IF(OR(BH14=1,BJ14=1),BS14,0) -> 0 | CA14: =IF(AND(C14="日",BJ14=0),BN14+BP14+BR14+BT14,0) -> 0 | CB14: =IF(AND(C14="日",BJ14=0),BS14,0) -> 0 | CC14: =MOD(ROUND(BY14+BZ14+CA14+CB14,2),ROUND($CC$7,2)) -> 0 | CD14: =IF(OR(AND(AJ14="直行",AN14="直帰"),AND(AJ14="",AN14="直帰"),AND(AJ14="直行",AN14="")),1,0) -> 0 | CK14: 金
A15: 27 | C15: 木 | M15: =IF(E15="","",IF((BO15+BQ15)=0,"",(BO15+BQ15)*60)) -> 60 | O15: =IF(E15<>"",IF(BU15<>0,BU15/24,""),"") -> 0.32291667 | S15: =IF(E15<>"",IF(BY15<>0,BY15/24,""),"") | W15: =IF(E15<>"",IF(BS15<>0,BS15/24,""),"") | AA15: =IF(E15<>"",IF(CA15<>0,CA15/24,""),"") | AP15: =IF(OR(AJ15<>"",AN15<>"",(BV15+BW15)<>0),IF(CD15=1,"","要"),IF(OR(S15<>"",W15<>"",AA15<>""),"申","")) | AV15: ～ | AZ15: ・ | BD15: =IF(ISERR(DAY(BG15)),1,IF(AND(DATEVALUE(BG15)>=DATEVALUE($BJ$5),DATEVALUE(BG15)<=DATEVALUE($BK$5)),0,1)) -> 0 | BE15: =IF($I$3=1,$A$3-1,$A$3) -> 2026 | BF15: =IF($I$3=1,12,IF($B$5=$O$5,IF($B$5<$I$3,$B$5,$B$5-1),$B$5)) -> 8 | BG15: =CONCATENATE(BE15,"/",BF15,"/",A15) -> 2026/8/27 | BH15: =IF(OR(COUNTIF(祝祭日!$A:$A,$BG15)>=1,OR(C15="土",C15="日",C15="",BD15=1)),0,1) -> 1 | BI15: =IF(OR(AJ15="有給休暇",AJ15="欠勤",AJ15="振替休日",AJ15="特別休暇"),1,0) -> 0 | BJ15: =IF(AJ15="振替予定休日出勤",1,0) -> 0 | BK15: =IF(AJ15="休日出勤",IF(C15="日",1,2),0) -> 0 | BL15: =IFERROR(IF(BI15=1,TIME(0,0,0),TIME(E15,G15,0)),TIME(0,0,0)) -> 0.375 | BM15: =IFERROR(IF(BI15=1,TIME(0,0,0),IF(E15>I15,TIME(I15,K15,0)+1,TIME(I15,K15,0))),TIME(0,0,0)) -> 0.73958333 | BN15: =TEXT(MAX(0,MIN($BM15,BN$7)-MAX($BL15,BN$6)),"h:mm")*24 -> 3 | BO15: =TEXT(MAX(0,MIN($BM15,BO$7)-MAX($BL15,BO$6)),"h:mm")*24 -> 1 | BP15: =TEXT(MAX(0,MIN($BM15,BP$7)-MAX($BL15,BP$6)),"h:mm")*24 -> 4.75 | BQ15: =TEXT(MAX(0,MIN($BM15,BQ$7)-MAX($BL15,BQ$6)),"h:mm")*24 -> 0 | BR15: =TEXT(MAX(0,MIN($BM15,BR$7)-MAX($BL15,BR$6)),"h:mm")*24-BQ15 -> 0 | BS15: =TEXT(MAX(0,MIN($BM15,BS$7)-MAX($BL15,BS$6)),"h:mm")*24 -> 0 | BT15: =TEXT(MAX(0,MIN($BM15,BT$7)-MAX($BL15,BT$6)),"h:mm")*24 -> 0 | BU15: =IF(OR(BH15=1,BJ15=1),BN15+BP15,0) -> 7.75 | BV15: =IF(BU15>0,IF(AJ15="遅刻（電車遅延）",0,$BH$3-BU15),0) -> 0 | BW15: =IF(AND(BU15>0,BV15=0),IF(MIN($BP$7,BM15)=BM15,($BP$7-BM15)*24,0),0) -> 0 | BX15: =MOD(ROUND(BV15+BW15,2),ROUND($BX$7,2)) -> 0 | BY15: =IF(OR(BH15=1,BJ15=1),BR15+BT15,IF(C15="日",0,BN15+BP15+BR15+BT15)) -> 0 | BZ15: =IF(OR(BH15=1,BJ15=1),BS15,0) -> 0 | CA15: =IF(AND(C15="日",BJ15=0),BN15+BP15+BR15+BT15,0) -> 0 | CB15: =IF(AND(C15="日",BJ15=0),BS15,0) -> 0 | CC15: =MOD(ROUND(BY15+BZ15+CA15+CB15,2),ROUND($CC$7,2)) -> 0 | CD15: =IF(OR(AND(AJ15="直行",AN15="直帰"),AND(AJ15="",AN15="直帰"),AND(AJ15="直行",AN15="")),1,0) -> 0 | CK15: 土
A16: 28 | C16: 金 | M16: =IF(E16="","",IF((BO16+BQ16)=0,"",(BO16+BQ16)*60)) -> 60 | O16: =IF(E16<>"",IF(BU16<>0,BU16/24,""),"") -> 0.32291667 | S16: =IF(E16<>"",IF(BY16<>0,BY16/24,""),"") | W16: =IF(E16<>"",IF(BS16<>0,BS16/24,""),"") | AA16: =IF(E16<>"",IF(CA16<>0,CA16/24,""),"") | AP16: =IF(OR(AJ16<>"",AN16<>"",(BV16+BW16)<>0),IF(CD16=1,"","要"),IF(OR(S16<>"",W16<>"",AA16<>""),"申","")) | AQ16: 平日実働時間 | AW16: 7 | AX16: 時間 | AZ16: 45 | BB16: 分 | BD16: =IF(ISERR(DAY(BG16)),1,IF(AND(DATEVALUE(BG16)>=DATEVALUE($BJ$5),DATEVALUE(BG16)<=DATEVALUE($BK$5)),0,1)) -> 0 | BE16: =IF($I$3=1,$A$3-1,$A$3) -> 2026 | BF16: =IF($I$3=1,12,IF($B$5=$O$5,IF($B$5<$I$3,$B$5,$B$5-1),$B$5)) -> 8 | BG16: =CONCATENATE(BE16,"/",BF16,"/",A16) -> 2026/8/28 | BH16: =IF(OR(COUNTIF(祝祭日!$A:$A,$BG16)>=1,OR(C16="土",C16="日",C16="",BD16=1)),0,1) -> 1 | BI16: =IF(OR(AJ16="有給休暇",AJ16="欠勤",AJ16="振替休日",AJ16="特別休暇"),1,0) -> 0 | BJ16: =IF(AJ16="振替予定休日出勤",1,0) -> 0 | BK16: =IF(AJ16="休日出勤",IF(C16="日",1,2),0) -> 0 | BL16: =IFERROR(IF(BI16=1,TIME(0,0,0),TIME(E16,G16,0)),TIME(0,0,0)) -> 0.375 | BM16: =IFERROR(IF(BI16=1,TIME(0,0,0),IF(E16>I16,TIME(I16,K16,0)+1,TIME(I16,K16,0))),TIME(0,0,0)) -> 0.73958333 | BN16: =TEXT(MAX(0,MIN($BM16,BN$7)-MAX($BL16,BN$6)),"h:mm")*24 -> 3 | BO16: =TEXT(MAX(0,MIN($BM16,BO$7)-MAX($BL16,BO$6)),"h:mm")*24 -> 1 | BP16: =TEXT(MAX(0,MIN($BM16,BP$7)-MAX($BL16,BP$6)),"h:mm")*24 -> 4.75 | BQ16: =TEXT(MAX(0,MIN($BM16,BQ$7)-MAX($BL16,BQ$6)),"h:mm")*24 -> 0 | BR16: =TEXT(MAX(0,MIN($BM16,BR$7)-MAX($BL16,BR$6)),"h:mm")*24-BQ16 -> 0 | BS16: =TEXT(MAX(0,MIN($BM16,BS$7)-MAX($BL16,BS$6)),"h:mm")*24 -> 0 | BT16: =TEXT(MAX(0,MIN($BM16,BT$7)-MAX($BL16,BT$6)),"h:mm")*24 -> 0 | BU16: =IF(OR(BH16=1,BJ16=1),BN16+BP16,0) -> 7.75 | BV16: =IF(BU16>0,IF(AJ16="遅刻（電車遅延）",0,$BH$3-BU16),0) -> 0 | BW16: =IF(AND(BU16>0,BV16=0),IF(MIN($BP$7,BM16)=BM16,($BP$7-BM16)*24,0),0) -> 0 | BX16: =MOD(ROUND(BV16+BW16,2),ROUND($BX$7,2)) -> 0 | BY16: =IF(OR(BH16=1,BJ16=1),BR16+BT16,IF(C16="日",0,BN16+BP16+BR16+BT16)) -> 0 | BZ16: =IF(OR(BH16=1,BJ16=1),BS16,0) -> 0 | CA16: =IF(AND(C16="日",BJ16=0),BN16+BP16+BR16+BT16,0) -> 0 | CB16: =IF(AND(C16="日",BJ16=0),BS16,0) -> 0 | CC16: =MOD(ROUND(BY16+BZ16+CA16+CB16,2),ROUND($CC$7,2)) -> 0 | CD16: =IF(OR(AND(AJ16="直行",AN16="直帰"),AND(AJ16="",AN16="直帰"),AND(AJ16="直行",AN16="")),1,0) -> 0 | CK16: 日
A17: 29 | C17: 土 | AP17: =IF(OR(AJ17<>"",AN17<>"",(BV17+BW17)<>0),IF(CD17=1,"","要"),IF(OR(S17<>"",W17<>"",AA17<>""),"申","")) | AQ17: 休日実働時間 | AW17: 7 | AX17: 時間 | AZ17: 45 | BB17: 分 | BD17: =IF(ISERR(DAY(BG17)),1,IF(AND(DATEVALUE(BG17)>=DATEVALUE($BJ$5),DATEVALUE(BG17)<=DATEVALUE($BK$5)),0,1)) -> 0 | BE17: =IF($I$3=1,$A$3-1,$A$3) -> 2026 | BF17: =IF($I$3=1,12,IF($B$5=$O$5,IF($B$5<$I$3,$B$5,$B$5-1),$B$5)) -> 8 | BG17: =CONCATENATE(BE17,"/",BF17,"/",A17) -> 2026/8/29 | BH17: =IF(OR(COUNTIF(祝祭日!$A:$A,$BG17)>=1,OR(C17="土",C17="日",C17="",BD17=1)),0,1) -> 0 | BI17: =IF(OR(AJ17="有給休暇",AJ17="欠勤",AJ17="振替休日",AJ17="特別休暇"),1,0) -> 0 | BJ17: =IF(AJ17="振替予定休日出勤",1,0) -> 0 | BK17: =IF(AJ17="休日出勤",IF(C17="日",1,2),0) -> 0 | BL17: =IFERROR(IF(BI17=1,TIME(0,0,0),TIME(E17,G17,0)),TIME(0,0,0)) -> 0 | BM17: =IFERROR(IF(BI17=1,TIME(0,0,0),IF(E17>I17,TIME(I17,K17,0)+1,TIME(I17,K17,0))),TIME(0,0,0)) -> 0 | BN17: =TEXT(MAX(0,MIN($BM17,BN$7)-MAX($BL17,BN$6)),"h:mm")*24 -> 0 | BO17: =TEXT(MAX(0,MIN($BM17,BO$7)-MAX($BL17,BO$6)),"h:mm")*24 -> 0 | BP17: =TEXT(MAX(0,MIN($BM17,BP$7)-MAX($BL17,BP$6)),"h:mm")*24 -> 0 | BQ17: =TEXT(MAX(0,MIN($BM17,BQ$7)-MAX($BL17,BQ$6)),"h:mm")*24 -> 0 | BR17: =TEXT(MAX(0,MIN($BM17,BR$7)-MAX($BL17,BR$6)),"h:mm")*24-BQ17 -> 0 | BS17: =TEXT(MAX(0,MIN($BM17,BS$7)-MAX($BL17,BS$6)),"h:mm")*24 -> 0 | BT17: =TEXT(MAX(0,MIN($BM17,BT$7)-MAX($BL17,BT$6)),"h:mm")*24 -> 0 | BU17: =IF(OR(BH17=1,BJ17=1),BN17+BP17,0) -> 0 | BV17: =IF(BU17>0,IF(AJ17="遅刻（電車遅延）",0,$BH$3-BU17),0) -> 0 | BW17: =IF(AND(BU17>0,BV17=0),IF(MIN($BP$7,BM17)=BM17,($BP$7-BM17)*24,0),0) -> 0 | BX17: =MOD(ROUND(BV17+BW17,2),ROUND($BX$7,2)) -> 0 | BY17: =IF(OR(BH17=1,BJ17=1),BR17+BT17,IF(C17="日",0,BN17+BP17+BR17+BT17)) -> 0 | BZ17: =IF(OR(BH17=1,BJ17=1),BS17,0) -> 0 | CA17: =IF(AND(C17="日",BJ17=0),BN17+BP17+BR17+BT17,0) -> 0 | CB17: =IF(AND(C17="日",BJ17=0),BS17,0) -> 0 | CC17: =MOD(ROUND(BY17+BZ17+CA17+CB17,2),ROUND($CC$7,2)) -> 0 | CD17: =IF(OR(AND(AJ17="直行",AN17="直帰"),AND(AJ17="",AN17="直帰"),AND(AJ17="直行",AN17="")),1,0) -> 0 | CK17: 月
A18: 30 | C18: 日 | AP18: =IF(OR(AJ18<>"",AN18<>"",(BV18+BW18)<>0),IF(CD18=1,"","要"),IF(OR(S18<>"",W18<>"",AA18<>""),"申","")) | AQ18: 所定休日 | BD18: =IF(ISERR(DAY(BG18)),1,IF(AND(DATEVALUE(BG18)>=DATEVALUE($BJ$5),DATEVALUE(BG18)<=DATEVALUE($BK$5)),0,1)) -> 0 | BE18: =IF($I$3=1,$A$3-1,$A$3) -> 2026 | BF18: =IF($I$3=1,12,IF($B$5=$O$5,IF($B$5<$I$3,$B$5,$B$5-1),$B$5)) -> 8 | BG18: =CONCATENATE(BE18,"/",BF18,"/",A18) -> 2026/8/30 | BH18: =IF(OR(COUNTIF(祝祭日!$A:$A,$BG18)>=1,OR(C18="土",C18="日",C18="",BD18=1)),0,1) -> 0 | BI18: =IF(OR(AJ18="有給休暇",AJ18="欠勤",AJ18="振替休日",AJ18="特別休暇"),1,0) -> 0 | BJ18: =IF(AJ18="振替予定休日出勤",1,0) -> 0 | BK18: =IF(AJ18="休日出勤",IF(C18="日",1,2),0) -> 0 | BL18: =IFERROR(IF(BI18=1,TIME(0,0,0),TIME(E18,G18,0)),TIME(0,0,0)) -> 0 | BM18: =IFERROR(IF(BI18=1,TIME(0,0,0),IF(E18>I18,TIME(I18,K18,0)+1,TIME(I18,K18,0))),TIME(0,0,0)) -> 0 | BN18: =TEXT(MAX(0,MIN($BM18,BN$7)-MAX($BL18,BN$6)),"h:mm")*24 -> 0 | BO18: =TEXT(MAX(0,MIN($BM18,BO$7)-MAX($BL18,BO$6)),"h:mm")*24 -> 0 | BP18: =TEXT(MAX(0,MIN($BM18,BP$7)-MAX($BL18,BP$6)),"h:mm")*24 -> 0 | BQ18: =TEXT(MAX(0,MIN($BM18,BQ$7)-MAX($BL18,BQ$6)),"h:mm")*24 -> 0 | BR18: =TEXT(MAX(0,MIN($BM18,BR$7)-MAX($BL18,BR$6)),"h:mm")*24-BQ18 -> 0 | BS18: =TEXT(MAX(0,MIN($BM18,BS$7)-MAX($BL18,BS$6)),"h:mm")*24 -> 0 | BT18: =TEXT(MAX(0,MIN($BM18,BT$7)-MAX($BL18,BT$6)),"h:mm")*24 -> 0 | BU18: =IF(OR(BH18=1,BJ18=1),BN18+BP18,0) -> 0 | BV18: =IF(BU18>0,IF(AJ18="遅刻（電車遅延）",0,$BH$3-BU18),0) -> 0 | BW18: =IF(AND(BU18>0,BV18=0),IF(MIN($BP$7,BM18)=BM18,($BP$7-BM18)*24,0),0) -> 0 | BX18: =MOD(ROUND(BV18+BW18,2),ROUND($BX$7,2)) -> 0 | BY18: =IF(OR(BH18=1,BJ18=1),BR18+BT18,IF(C18="日",0,BN18+BP18+BR18+BT18)) -> 0 | BZ18: =IF(OR(BH18=1,BJ18=1),BS18,0) -> 0 | CA18: =IF(AND(C18="日",BJ18=0),BN18+BP18+BR18+BT18,0) -> 0 | CB18: =IF(AND(C18="日",BJ18=0),BS18,0) -> 0 | CC18: =MOD(ROUND(BY18+BZ18+CA18+CB18,2),ROUND($CC$7,2)) -> 0 | CD18: =IF(OR(AND(AJ18="直行",AN18="直帰"),AND(AJ18="",AN18="直帰"),AND(AJ18="直行",AN18="")),1,0) -> 0 | CK18: 火
A19: 31 | C19: 月 | M19: =IF(E19="","",IF((BO19+BQ19)=0,"",(BO19+BQ19)*60)) -> 60 | O19: =IF(E19<>"",IF(BU19<>0,BU19/24,""),"") -> 0.32291667 | W19: =IF(E19<>"",IF(BS19<>0,BS19/24,""),"") | AA19: =IF(E19<>"",IF(CA19<>0,CA19/24,""),"") | AP19: =IF(OR(AJ19<>"",AN19<>"",(BV19+BW19)<>0),IF(CD19=1,"","要"),IF(OR(S19<>"",W19<>"",AA19<>""),"申","")) | BD19: =IF(ISERR(DAY(BG19)),1,IF(AND(DATEVALUE(BG19)>=DATEVALUE($BJ$5),DATEVALUE(BG19)<=DATEVALUE($BK$5)),0,1)) -> 0 | BE19: =IF($I$3=1,$A$3-1,$A$3) -> 2026 | BF19: =IF($I$3=1,12,IF($B$5=$O$5,IF($B$5<$I$3,$B$5,$B$5-1),$B$5)) -> 8 | BG19: =CONCATENATE(BE19,"/",BF19,"/",A19) -> 2026/8/31 | BH19: =IF(OR(COUNTIF(祝祭日!$A:$A,$BG19)>=1,OR(C19="土",C19="日",C19="",BD19=1)),0,1) -> 1 | BI19: =IF(OR(AJ19="有給休暇",AJ19="欠勤",AJ19="振替休日",AJ19="特別休暇"),1,0) -> 0 | BJ19: =IF(AJ19="振替予定休日出勤",1,0) -> 0 | BK19: =IF(AJ19="休日出勤",IF(C19="日",1,2),0) -> 0 | BL19: =IFERROR(IF(BI19=1,TIME(0,0,0),TIME(E19,G19,0)),TIME(0,0,0)) -> 0.375 | BM19: =IFERROR(IF(BI19=1,TIME(0,0,0),IF(E19>I19,TIME(I19,K19,0)+1,TIME(I19,K19,0))),TIME(0,0,0)) -> 0.73958333 | BN19: =TEXT(MAX(0,MIN($BM19,BN$7)-MAX($BL19,BN$6)),"h:mm")*24 -> 3 | BO19: =TEXT(MAX(0,MIN($BM19,BO$7)-MAX($BL19,BO$6)),"h:mm")*24 -> 1 | BP19: =TEXT(MAX(0,MIN($BM19,BP$7)-MAX($BL19,BP$6)),"h:mm")*24 -> 4.75 | BQ19: =TEXT(MAX(0,MIN($BM19,BQ$7)-MAX($BL19,BQ$6)),"h:mm")*24 -> 0 | BR19: =TEXT(MAX(0,MIN($BM19,BR$7)-MAX($BL19,BR$6)),"h:mm")*24-BQ19 -> 0 | BS19: =TEXT(MAX(0,MIN($BM19,BS$7)-MAX($BL19,BS$6)),"h:mm")*24 -> 0 | BT19: =TEXT(MAX(0,MIN($BM19,BT$7)-MAX($BL19,BT$6)),"h:mm")*24 -> 0 | BU19: =IF(OR(BH19=1,BJ19=1),BN19+BP19,0) -> 7.75 | BV19: =IF(BU19>0,IF(AJ19="遅刻（電車遅延）",0,$BH$3-BU19),0) -> 0 | BW19: =IF(AND(BU19>0,BV19=0),IF(MIN($BP$7,BM19)=BM19,($BP$7-BM19)*24,0),0) -> 0 | BX19: =MOD(ROUND(BV19+BW19,2),ROUND($BX$7,2)) -> 0 | BY19: =IF(OR(BH19=1,BJ19=1),BR19+BT19,IF(C19="日",0,BN19+BP19+BR19+BT19)) -> 0 | BZ19: =IF(OR(BH19=1,BJ19=1),BS19,0) -> 0 | CA19: =IF(AND(C19="日",BJ19=0),BN19+BP19+BR19+BT19,0) -> 0 | CB19: =IF(AND(C19="日",BJ19=0),BS19,0) -> 0 | CC19: =MOD(ROUND(BY19+BZ19+CA19+CB19,2),ROUND($CC$7,2)) -> 0 | CD19: =IF(OR(AND(AJ19="直行",AN19="直帰"),AND(AJ19="",AN19="直帰"),AND(AJ19="直行",AN19="")),1,0) -> 0 | CK19: 水
A20: 1 | C20: 火 | M20: =IF(E20="","",IF((BO20+BQ20)=0,"",(BO20+BQ20)*60)) -> 60 | O20: =IF(E20<>"",IF(BU20<>0,BU20/24,""),"") -> 0.32291667 | S20: =IF(E20<>"",IF(BY20<>0,BY20/24,""),"") | W20: =IF(E20<>"",IF(BS20<>0,BS20/24,""),"") | AA20: =IF(E20<>"",IF(CA20<>0,CA20/24,""),"") | AP20: =IF(OR(AJ20<>"",AN20<>"",(BV20+BW20)<>0),IF(CD20=1,"","要"),IF(OR(S20<>"",W20<>"",AA20<>""),"申","")) | AQ20: 土曜日・日曜日・祝祭日 | BD20: =IF(ISERR(DAY(BG20)),1,IF(AND(DATEVALUE(BG20)>=DATEVALUE($BJ$5),DATEVALUE(BG20)<=DATEVALUE($BK$5)),0,1)) -> 0 | BE20: =$A$3 -> 2026 | BF20: =IF($B$5=$O$5,IF($B$5<$I$3,$B$5+1,$B$5),$I$3) -> 9 | BG20: =CONCATENATE(BE20,"/",BF20,"/",A20) -> 2026/9/1 | BH20: =IF(OR(COUNTIF(祝祭日!$A:$A,$BG20)>=1,OR(C20="土",C20="日",C20="",BD20=1)),0,1) -> 1 | BI20: =IF(OR(AJ20="有給休暇",AJ20="欠勤",AJ20="振替休日",AJ20="特別休暇"),1,0) -> 0 | BJ20: =IF(AJ20="振替予定休日出勤",1,0) -> 0 | BK20: =IF(AJ20="休日出勤",IF(C20="日",1,2),0) -> 0 | BL20: =IFERROR(IF(BI20=1,TIME(0,0,0),TIME(E20,G20,0)),TIME(0,0,0)) -> 0.375 | BM20: =IFERROR(IF(BI20=1,TIME(0,0,0),IF(E20>I20,TIME(I20,K20,0)+1,TIME(I20,K20,0))),TIME(0,0,0)) -> 0.73958333 | BN20: =TEXT(MAX(0,MIN($BM20,BN$7)-MAX($BL20,BN$6)),"h:mm")*24 -> 3 | BO20: =TEXT(MAX(0,MIN($BM20,BO$7)-MAX($BL20,BO$6)),"h:mm")*24 -> 1 | BP20: =TEXT(MAX(0,MIN($BM20,BP$7)-MAX($BL20,BP$6)),"h:mm")*24 -> 4.75 | BQ20: =TEXT(MAX(0,MIN($BM20,BQ$7)-MAX($BL20,BQ$6)),"h:mm")*24 -> 0 | BR20: =TEXT(MAX(0,MIN($BM20,BR$7)-MAX($BL20,BR$6)),"h:mm")*24-BQ20 -> 0 | BS20: =TEXT(MAX(0,MIN($BM20,BS$7)-MAX($BL20,BS$6)),"h:mm")*24 -> 0 | BT20: =TEXT(MAX(0,MIN($BM20,BT$7)-MAX($BL20,BT$6)),"h:mm")*24 -> 0 | BU20: =IF(OR(BH20=1,BJ20=1),BN20+BP20,0) -> 7.75 | BV20: =IF(BU20>0,IF(AJ20="遅刻（電車遅延）",0,$BH$3-BU20),0) -> 0 | BW20: =IF(AND(BU20>0,BV20=0),IF(MIN($BP$7,BM20)=BM20,($BP$7-BM20)*24,0),0) -> 0 | BX20: =MOD(ROUND(BV20+BW20,2),ROUND($BX$7,2)) -> 0 | BY20: =IF(OR(BH20=1,BJ20=1),BR20+BT20,IF(C20="日",0,BN20+BP20+BR20+BT20)) -> 0 | BZ20: =IF(OR(BH20=1,BJ20=1),BS20,0) -> 0 | CA20: =IF(AND(C20="日",BJ20=0),BN20+BP20+BR20+BT20,0) -> 0 | CB20: =IF(AND(C20="日",BJ20=0),BS20,0) -> 0 | CC20: =MOD(ROUND(BY20+BZ20+CA20+CB20,2),ROUND($CC$7,2)) -> 0 | CD20: =IF(OR(AND(AJ20="直行",AN20="直帰"),AND(AJ20="",AN20="直帰"),AND(AJ20="直行",AN20="")),1,0) -> 0 | CK20: 木
A21: 2 | C21: 水 | M21: =IF(E21="","",IF((BO21+BQ21)=0,"",(BO21+BQ21)*60)) -> 60 | O21: =IF(E21<>"",IF(BU21<>0,BU21/24,""),"") -> 0.32291667 | S21: =IF(E21<>"",IF(BY21<>0,BY21/24,""),"") | W21: =IF(E21<>"",IF(BS21<>0,BS21/24,""),"") | AA21: =IF(E21<>"",IF(CA21<>0,CA21/24,""),"") | AP21: =IF(OR(AJ21<>"",AN21<>"",(BV21+BW21)<>0),IF(CD21=1,"","要"),IF(OR(S21<>"",W21<>"",AA21<>""),"申","")) | AQ21: 時間外勤務時間 | BD21: =IF(ISERR(DAY(BG21)),1,IF(AND(DATEVALUE(BG21)>=DATEVALUE($BJ$5),DATEVALUE(BG21)<=DATEVALUE($BK$5)),0,1)) -> 0 | BE21: =$A$3 -> 2026 | BF21: =IF($B$5=$O$5,IF($B$5<$I$3,$B$5+1,$B$5),$I$3) -> 9 | BG21: =CONCATENATE(BE21,"/",BF21,"/",A21) -> 2026/9/2 | BH21: =IF(OR(COUNTIF(祝祭日!$A:$A,$BG21)>=1,OR(C21="土",C21="日",C21="",BD21=1)),0,1) -> 1 | BI21: =IF(OR(AJ21="有給休暇",AJ21="欠勤",AJ21="振替休日",AJ21="特別休暇"),1,0) -> 0 | BJ21: =IF(AJ21="振替予定休日出勤",1,0) -> 0 | BK21: =IF(AJ21="休日出勤",IF(C21="日",1,2),0) -> 0 | BL21: =IFERROR(IF(BI21=1,TIME(0,0,0),TIME(E21,G21,0)),TIME(0,0,0)) -> 0.375 | BM21: =IFERROR(IF(BI21=1,TIME(0,0,0),IF(E21>I21,TIME(I21,K21,0)+1,TIME(I21,K21,0))),TIME(0,0,0)) -> 0.73958333 | BN21: =TEXT(MAX(0,MIN($BM21,BN$7)-MAX($BL21,BN$6)),"h:mm")*24 -> 3 | BO21: =TEXT(MAX(0,MIN($BM21,BO$7)-MAX($BL21,BO$6)),"h:mm")*24 -> 1 | BP21: =TEXT(MAX(0,MIN($BM21,BP$7)-MAX($BL21,BP$6)),"h:mm")*24 -> 4.75 | BQ21: =TEXT(MAX(0,MIN($BM21,BQ$7)-MAX($BL21,BQ$6)),"h:mm")*24 -> 0 | BR21: =TEXT(MAX(0,MIN($BM21,BR$7)-MAX($BL21,BR$6)),"h:mm")*24-BQ21 -> 0 | BS21: =TEXT(MAX(0,MIN($BM21,BS$7)-MAX($BL21,BS$6)),"h:mm")*24 -> 0 | BT21: =TEXT(MAX(0,MIN($BM21,BT$7)-MAX($BL21,BT$6)),"h:mm")*24 -> 0 | BU21: =IF(OR(BH21=1,BJ21=1),BN21+BP21,0) -> 7.75 | BV21: =IF(BU21>0,IF(AJ21="遅刻（電車遅延）",0,$BH$3-BU21),0) -> 0 | BW21: =IF(AND(BU21>0,BV21=0),IF(MIN($BP$7,BM21)=BM21,($BP$7-BM21)*24,0),0) -> 0 | BX21: =MOD(ROUND(BV21+BW21,2),ROUND($BX$7,2)) -> 0 | BY21: =IF(OR(BH21=1,BJ21=1),BR21+BT21,IF(C21="日",0,BN21+BP21+BR21+BT21)) -> 0 | BZ21: =IF(OR(BH21=1,BJ21=1),BS21,0) -> 0 | CA21: =IF(AND(C21="日",BJ21=0),BN21+BP21+BR21+BT21,0) -> 0 | CB21: =IF(AND(C21="日",BJ21=0),BS21,0) -> 0 | CC21: =MOD(ROUND(BY21+BZ21+CA21+CB21,2),ROUND($CC$7,2)) -> 0 | CD21: =IF(OR(AND(AJ21="直行",AN21="直帰"),AND(AJ21="",AN21="直帰"),AND(AJ21="直行",AN21="")),1,0) -> 0 | CK21: 金
A22: 3 | C22: 木 | M22: =IF(E22="","",IF((BO22+BQ22)=0,"",(BO22+BQ22)*60)) -> 60 | O22: =IF(E22<>"",IF(BU22<>0,BU22/24,""),"") -> 0.32291667 | S22: =IF(E22<>"",IF(BY22<>0,BY22/24,""),"") | W22: =IF(E22<>"",IF(BS22<>0,BS22/24,""),"") | AA22: =IF(E22<>"",IF(CA22<>0,CA22/24,""),"") | AP22: =IF(OR(AJ22<>"",AN22<>"",(BV22+BW22)<>0),IF(CD22=1,"","要"),IF(OR(S22<>"",W22<>"",AA22<>""),"申","")) | BD22: =IF(ISERR(DAY(BG22)),1,IF(AND(DATEVALUE(BG22)>=DATEVALUE($BJ$5),DATEVALUE(BG22)<=DATEVALUE($BK$5)),0,1)) -> 0 | BE22: =$A$3 -> 2026 | BF22: =IF($B$5=$O$5,IF($B$5<$I$3,$B$5+1,$B$5),$I$3) -> 9 | BG22: =CONCATENATE(BE22,"/",BF22,"/",A22) -> 2026/9/3 | BH22: =IF(OR(COUNTIF(祝祭日!$A:$A,$BG22)>=1,OR(C22="土",C22="日",C22="",BD22=1)),0,1) -> 1 | BI22: =IF(OR(AJ22="有給休暇",AJ22="欠勤",AJ22="振替休日",AJ22="特別休暇"),1,0) -> 0 | BJ22: =IF(AJ22="振替予定休日出勤",1,0) -> 0 | BK22: =IF(AJ22="休日出勤",IF(C22="日",1,2),0) -> 0 | BL22: =IFERROR(IF(BI22=1,TIME(0,0,0),TIME(E22,G22,0)),TIME(0,0,0)) -> 0.375 | BM22: =IFERROR(IF(BI22=1,TIME(0,0,0),IF(E22>I22,TIME(I22,K22,0)+1,TIME(I22,K22,0))),TIME(0,0,0)) -> 0.73958333 | BN22: =TEXT(MAX(0,MIN($BM22,BN$7)-MAX($BL22,BN$6)),"h:mm")*24 -> 3 | BO22: =TEXT(MAX(0,MIN($BM22,BO$7)-MAX($BL22,BO$6)),"h:mm")*24 -> 1 | BP22: =TEXT(MAX(0,MIN($BM22,BP$7)-MAX($BL22,BP$6)),"h:mm")*24 -> 4.75 | BQ22: =TEXT(MAX(0,MIN($BM22,BQ$7)-MAX($BL22,BQ$6)),"h:mm")*24 -> 0 | BR22: =TEXT(MAX(0,MIN($BM22,BR$7)-MAX($BL22,BR$6)),"h:mm")*24-BQ22 -> 0 | BS22: =TEXT(MAX(0,MIN($BM22,BS$7)-MAX($BL22,BS$6)),"h:mm")*24 -> 0 | BT22: =TEXT(MAX(0,MIN($BM22,BT$7)-MAX($BL22,BT$6)),"h:mm")*24 -> 0 | BU22: =IF(OR(BH22=1,BJ22=1),BN22+BP22,0) -> 7.75 | BV22: =IF(BU22>0,IF(AJ22="遅刻（電車遅延）",0,$BH$3-BU22),0) -> 0 | BW22: =IF(AND(BU22>0,BV22=0),IF(MIN($BP$7,BM22)=BM22,($BP$7-BM22)*24,0),0) -> 0 | BX22: =MOD(ROUND(BV22+BW22,2),ROUND($BX$7,2)) -> 0 | BY22: =IF(OR(BH22=1,BJ22=1),BR22+BT22,IF(C22="日",0,BN22+BP22+BR22+BT22)) -> 0 | BZ22: =IF(OR(BH22=1,BJ22=1),BS22,0) -> 0 | CA22: =IF(AND(C22="日",BJ22=0),BN22+BP22+BR22+BT22,0) -> 0 | CB22: =IF(AND(C22="日",BJ22=0),BS22,0) -> 0 | CC22: =MOD(ROUND(BY22+BZ22+CA22+CB22,2),ROUND($CC$7,2)) -> 0 | CD22: =IF(OR(AND(AJ22="直行",AN22="直帰"),AND(AJ22="",AN22="直帰"),AND(AJ22="直行",AN22="")),1,0) -> 0 | CK22: 土
A23: 4 | C23: 金 | M23: =IF(E23="","",IF((BO23+BQ23)=0,"",(BO23+BQ23)*60)) -> 60 | O23: =IF(E23<>"",IF(BU23<>0,BU23/24,""),"") -> 0.32291667 | S23: =IF(E23<>"",IF(BY23<>0,BY23/24,""),"") | W23: =IF(E23<>"",IF(BS23<>0,BS23/24,""),"") | AP23: =IF(OR(AJ23<>"",AN23<>"",(BV23+BW23)<>0),IF(CD23=1,"","要"),IF(OR(S23<>"",W23<>"",AA23<>""),"申","")) | AQ23: 平日 | AS23: 実働８時間以上 | BD23: =IF(ISERR(DAY(BG23)),1,IF(AND(DATEVALUE(BG23)>=DATEVALUE($BJ$5),DATEVALUE(BG23)<=DATEVALUE($BK$5)),0,1)) -> 0 | BE23: =$A$3 -> 2026 | BF23: =IF($B$5=$O$5,IF($B$5<$I$3,$B$5+1,$B$5),$I$3) -> 9 | BG23: =CONCATENATE(BE23,"/",BF23,"/",A23) -> 2026/9/4 | BH23: =IF(OR(COUNTIF(祝祭日!$A:$A,$BG23)>=1,OR(C23="土",C23="日",C23="",BD23=1)),0,1) -> 1 | BI23: =IF(OR(AJ23="有給休暇",AJ23="欠勤",AJ23="振替休日",AJ23="特別休暇"),1,0) -> 0 | BJ23: =IF(AJ23="振替予定休日出勤",1,0) -> 0 | BK23: =IF(AJ23="休日出勤",IF(C23="日",1,2),0) -> 0 | BL23: =IFERROR(IF(BI23=1,TIME(0,0,0),TIME(E23,G23,0)),TIME(0,0,0)) -> 0.375 | BM23: =IFERROR(IF(BI23=1,TIME(0,0,0),IF(E23>I23,TIME(I23,K23,0)+1,TIME(I23,K23,0))),TIME(0,0,0)) -> 0.73958333 | BN23: =TEXT(MAX(0,MIN($BM23,BN$7)-MAX($BL23,BN$6)),"h:mm")*24 -> 3 | BO23: =TEXT(MAX(0,MIN($BM23,BO$7)-MAX($BL23,BO$6)),"h:mm")*24 -> 1 | BP23: =TEXT(MAX(0,MIN($BM23,BP$7)-MAX($BL23,BP$6)),"h:mm")*24 -> 4.75 | BQ23: =TEXT(MAX(0,MIN($BM23,BQ$7)-MAX($BL23,BQ$6)),"h:mm")*24 -> 0 | BR23: =TEXT(MAX(0,MIN($BM23,BR$7)-MAX($BL23,BR$6)),"h:mm")*24-BQ23 -> 0 | BS23: =TEXT(MAX(0,MIN($BM23,BS$7)-MAX($BL23,BS$6)),"h:mm")*24 -> 0 | BT23: =TEXT(MAX(0,MIN($BM23,BT$7)-MAX($BL23,BT$6)),"h:mm")*24 -> 0 | BU23: =IF(OR(BH23=1,BJ23=1),BN23+BP23,0) -> 7.75 | BV23: =IF(BU23>0,IF(AJ23="遅刻（電車遅延）",0,$BH$3-BU23),0) -> 0 | BW23: =IF(AND(BU23>0,BV23=0),IF(MIN($BP$7,BM23)=BM23,($BP$7-BM23)*24,0),0) -> 0 | BX23: =MOD(ROUND(BV23+BW23,2),ROUND($BX$7,2)) -> 0 | BY23: =IF(OR(BH23=1,BJ23=1),BR23+BT23,IF(C23="日",0,BN23+BP23+BR23+BT23)) -> 0 | BZ23: =IF(OR(BH23=1,BJ23=1),BS23,0) -> 0 | CA23: =IF(AND(C23="日",BJ23=0),BN23+BP23+BR23+BT23,0) -> 0 | CB23: =IF(AND(C23="日",BJ23=0),BS23,0) -> 0 | CC23: =MOD(ROUND(BY23+BZ23+CA23+CB23,2),ROUND($CC$7,2)) -> 0 | CD23: =IF(OR(AND(AJ23="直行",AN23="直帰"),AND(AJ23="",AN23="直帰"),AND(AJ23="直行",AN23="")),1,0) -> 0 | CK23: 日
A24: 5 | C24: 土 | AP24: =IF(OR(AJ24<>"",AN24<>"",(BV24+BW24)<>0),IF(CD24=1,"","要"),IF(OR(S24<>"",W24<>"",AA24<>""),"申","")) | AQ24: 割増単位 | AW24: 15 | BA24: 分 | BD24: =IF(ISERR(DAY(BG24)),1,IF(AND(DATEVALUE(BG24)>=DATEVALUE($BJ$5),DATEVALUE(BG24)<=DATEVALUE($BK$5)),0,1)) -> 0 | BE24: =$A$3 -> 2026 | BF24: =IF($B$5=$O$5,IF($B$5<$I$3,$B$5+1,$B$5),$I$3) -> 9 | BG24: =CONCATENATE(BE24,"/",BF24,"/",A24) -> 2026/9/5 | BH24: =IF(OR(COUNTIF(祝祭日!$A:$A,$BG24)>=1,OR(C24="土",C24="日",C24="",BD24=1)),0,1) -> 0 | BI24: =IF(OR(AJ24="有給休暇",AJ24="欠勤",AJ24="振替休日",AJ24="特別休暇"),1,0) -> 0 | BJ24: =IF(AJ24="振替予定休日出勤",1,0) -> 0 | BK24: =IF(AJ24="休日出勤",IF(C24="日",1,2),0) -> 0 | BL24: =IFERROR(IF(BI24=1,TIME(0,0,0),TIME(E24,G24,0)),TIME(0,0,0)) -> 0 | BM24: =IFERROR(IF(BI24=1,TIME(0,0,0),IF(E24>I24,TIME(I24,K24,0)+1,TIME(I24,K24,0))),TIME(0,0,0)) -> 0 | BN24: =TEXT(MAX(0,MIN($BM24,BN$7)-MAX($BL24,BN$6)),"h:mm")*24 -> 0 | BO24: =TEXT(MAX(0,MIN($BM24,BO$7)-MAX($BL24,BO$6)),"h:mm")*24 -> 0 | BP24: =TEXT(MAX(0,MIN($BM24,BP$7)-MAX($BL24,BP$6)),"h:mm")*24 -> 0 | BQ24: =TEXT(MAX(0,MIN($BM24,BQ$7)-MAX($BL24,BQ$6)),"h:mm")*24 -> 0 | BR24: =TEXT(MAX(0,MIN($BM24,BR$7)-MAX($BL24,BR$6)),"h:mm")*24-BQ24 -> 0 | BS24: =TEXT(MAX(0,MIN($BM24,BS$7)-MAX($BL24,BS$6)),"h:mm")*24 -> 0 | BT24: =TEXT(MAX(0,MIN($BM24,BT$7)-MAX($BL24,BT$6)),"h:mm")*24 -> 0 | BU24: =IF(OR(BH24=1,BJ24=1),BN24+BP24,0) -> 0 | BV24: =IF(BU24>0,IF(AJ24="遅刻（電車遅延）",0,$BH$3-BU24),0) -> 0 | BW24: =IF(AND(BU24>0,BV24=0),IF(MIN($BP$7,BM24)=BM24,($BP$7-BM24)*24,0),0) -> 0 | BX24: =MOD(ROUND(BV24+BW24,2),ROUND($BX$7,2)) -> 0 | BY24: =IF(OR(BH24=1,BJ24=1),BR24+BT24,IF(C24="日",0,BN24+BP24+BR24+BT24)) -> 0 | BZ24: =IF(OR(BH24=1,BJ24=1),BS24,0) -> 0 | CA24: =IF(AND(C24="日",BJ24=0),BN24+BP24+BR24+BT24,0) -> 0 | CB24: =IF(AND(C24="日",BJ24=0),BS24,0) -> 0 | CC24: =MOD(ROUND(BY24+BZ24+CA24+CB24,2),ROUND($CC$7,2)) -> 0 | CD24: =IF(OR(AND(AJ24="直行",AN24="直帰"),AND(AJ24="",AN24="直帰"),AND(AJ24="直行",AN24="")),1,0) -> 0 | CK24: 月
A25: 6 | C25: 日 | AP25: =IF(OR(AJ25<>"",AN25<>"",(BV25+BW25)<>0),IF(CD25=1,"","要"),IF(OR(S25<>"",W25<>"",AA25<>""),"申","")) | AQ25: 控除 | BD25: =IF(ISERR(DAY(BG25)),1,IF(AND(DATEVALUE(BG25)>=DATEVALUE($BJ$5),DATEVALUE(BG25)<=DATEVALUE($BK$5)),0,1)) -> 0 | BE25: =$A$3 -> 2026 | BF25: =IF($B$5=$O$5,IF($B$5<$I$3,$B$5+1,$B$5),$I$3) -> 9 | BG25: =CONCATENATE(BE25,"/",BF25,"/",A25) -> 2026/9/6 | BH25: =IF(OR(COUNTIF(祝祭日!$A:$A,$BG25)>=1,OR(C25="土",C25="日",C25="",BD25=1)),0,1) -> 0 | BI25: =IF(OR(AJ25="有給休暇",AJ25="欠勤",AJ25="振替休日",AJ25="特別休暇"),1,0) -> 0 | BJ25: =IF(AJ25="振替予定休日出勤",1,0) -> 0 | BK25: =IF(AJ25="休日出勤",IF(C25="日",1,2),0) -> 0 | BL25: =IFERROR(IF(BI25=1,TIME(0,0,0),TIME(E25,G25,0)),TIME(0,0,0)) -> 0 | BM25: =IFERROR(IF(BI25=1,TIME(0,0,0),IF(E25>I25,TIME(I25,K25,0)+1,TIME(I25,K25,0))),TIME(0,0,0)) -> 0 | BN25: =TEXT(MAX(0,MIN($BM25,BN$7)-MAX($BL25,BN$6)),"h:mm")*24 -> 0 | BO25: =TEXT(MAX(0,MIN($BM25,BO$7)-MAX($BL25,BO$6)),"h:mm")*24 -> 0 | BP25: =TEXT(MAX(0,MIN($BM25,BP$7)-MAX($BL25,BP$6)),"h:mm")*24 -> 0 | BQ25: =TEXT(MAX(0,MIN($BM25,BQ$7)-MAX($BL25,BQ$6)),"h:mm")*24 -> 0 | BR25: =TEXT(MAX(0,MIN($BM25,BR$7)-MAX($BL25,BR$6)),"h:mm")*24-BQ25 -> 0 | BS25: =TEXT(MAX(0,MIN($BM25,BS$7)-MAX($BL25,BS$6)),"h:mm")*24 -> 0 | BT25: =TEXT(MAX(0,MIN($BM25,BT$7)-MAX($BL25,BT$6)),"h:mm")*24 -> 0 | BU25: =IF(OR(BH25=1,BJ25=1),BN25+BP25,0) -> 0 | BV25: =IF(BU25>0,IF(AJ25="遅刻（電車遅延）",0,$BH$3-BU25),0) -> 0 | BW25: =IF(AND(BU25>0,BV25=0),IF(MIN($BP$7,BM25)=BM25,($BP$7-BM25)*24,0),0) -> 0 | BX25: =MOD(ROUND(BV25+BW25,2),ROUND($BX$7,2)) -> 0 | BY25: =IF(OR(BH25=1,BJ25=1),BR25+BT25,IF(C25="日",0,BN25+BP25+BR25+BT25)) -> 0 | BZ25: =IF(OR(BH25=1,BJ25=1),BS25,0) -> 0 | CA25: =IF(AND(C25="日",BJ25=0),BN25+BP25+BR25+BT25,0) -> 0 | CB25: =IF(AND(C25="日",BJ25=0),BS25,0) -> 0 | CC25: =MOD(ROUND(BY25+BZ25+CA25+CB25,2),ROUND($CC$7,2)) -> 0 | CD25: =IF(OR(AND(AJ25="直行",AN25="直帰"),AND(AJ25="",AN25="直帰"),AND(AJ25="直行",AN25="")),1,0) -> 0 | CK25: 火
A26: 7 | C26: 月 | M26: =IF(E26="","",IF((BO26+BQ26)=0,"",(BO26+BQ26)*60)) -> 60 | O26: =IF(E26<>"",IF(BU26<>0,BU26/24,""),"") -> 0.32291667 | S26: =IF(E26<>"",IF(BY26<>0,BY26/24,""),"") | W26: =IF(E26<>"",IF(BS26<>0,BS26/24,""),"") | AA26: =IF(E26<>"",IF(CA26<>0,CA26/24,""),"") | AP26: =IF(OR(AJ26<>"",AN26<>"",(BV26+BW26)<>0),IF(CD26=1,"","要"),IF(OR(S26<>"",W26<>"",AA26<>""),"申","")) | BD26: =IF(ISERR(DAY(BG26)),1,IF(AND(DATEVALUE(BG26)>=DATEVALUE($BJ$5),DATEVALUE(BG26)<=DATEVALUE($BK$5)),0,1)) -> 0 | BE26: =$A$3 -> 2026 | BF26: =IF($B$5=$O$5,IF($B$5<$I$3,$B$5+1,$B$5),$I$3) -> 9 | BG26: =CONCATENATE(BE26,"/",BF26,"/",A26) -> 2026/9/7 | BH26: =IF(OR(COUNTIF(祝祭日!$A:$A,$BG26)>=1,OR(C26="土",C26="日",C26="",BD26=1)),0,1) -> 1 | BI26: =IF(OR(AJ26="有給休暇",AJ26="欠勤",AJ26="振替休日",AJ26="特別休暇"),1,0) -> 0 | BJ26: =IF(AJ26="振替予定休日出勤",1,0) -> 0 | BK26: =IF(AJ26="休日出勤",IF(C26="日",1,2),0) -> 0 | BL26: =IFERROR(IF(BI26=1,TIME(0,0,0),TIME(E26,G26,0)),TIME(0,0,0)) -> 0.375 | BM26: =IFERROR(IF(BI26=1,TIME(0,0,0),IF(E26>I26,TIME(I26,K26,0)+1,TIME(I26,K26,0))),TIME(0,0,0)) -> 0.73958333 | BN26: =TEXT(MAX(0,MIN($BM26,BN$7)-MAX($BL26,BN$6)),"h:mm")*24 -> 3 | BO26: =TEXT(MAX(0,MIN($BM26,BO$7)-MAX($BL26,BO$6)),"h:mm")*24 -> 1 | BP26: =TEXT(MAX(0,MIN($BM26,BP$7)-MAX($BL26,BP$6)),"h:mm")*24 -> 4.75 | BQ26: =TEXT(MAX(0,MIN($BM26,BQ$7)-MAX($BL26,BQ$6)),"h:mm")*24 -> 0 | BR26: =TEXT(MAX(0,MIN($BM26,BR$7)-MAX($BL26,BR$6)),"h:mm")*24-BQ26 -> 0 | BS26: =TEXT(MAX(0,MIN($BM26,BS$7)-MAX($BL26,BS$6)),"h:mm")*24 -> 0 | BT26: =TEXT(MAX(0,MIN($BM26,BT$7)-MAX($BL26,BT$6)),"h:mm")*24 -> 0 | BU26: =IF(OR(BH26=1,BJ26=1),BN26+BP26,0) -> 7.75 | BV26: =IF(BU26>0,IF(AJ26="遅刻（電車遅延）",0,$BH$3-BU26),0) -> 0 | BW26: =IF(AND(BU26>0,BV26=0),IF(MIN($BP$7,BM26)=BM26,($BP$7-BM26)*24,0),0) -> 0 | BX26: =MOD(ROUND(BV26+BW26,2),ROUND($BX$7,2)) -> 0 | BY26: =IF(OR(BH26=1,BJ26=1),BR26+BT26,IF(C26="日",0,BN26+BP26+BR26+BT26)) -> 0 | BZ26: =IF(OR(BH26=1,BJ26=1),BS26,0) -> 0 | CA26: =IF(AND(C26="日",BJ26=0),BN26+BP26+BR26+BT26,0) -> 0 | CB26: =IF(AND(C26="日",BJ26=0),BS26,0) -> 0 | CC26: =MOD(ROUND(BY26+BZ26+CA26+CB26,2),ROUND($CC$7,2)) -> 0 | CD26: =IF(OR(AND(AJ26="直行",AN26="直帰"),AND(AJ26="",AN26="直帰"),AND(AJ26="直行",AN26="")),1,0) -> 0 | CK26: 水
A27: 8 | C27: 火 | M27: =IF(E27="","",IF((BO27+BQ27)=0,"",(BO27+BQ27)*60)) -> 60 | O27: =IF(E27<>"",IF(BU27<>0,BU27/24,""),"") -> 0.32291667 | S27: =IF(E27<>"",IF(BY27<>0,BY27/24,""),"") | W27: =IF(E27<>"",IF(BS27<>0,BS27/24,""),"") | AA27: =IF(E27<>"",IF(CA27<>0,CA27/24,""),"") | AP27: =IF(OR(AJ27<>"",AN27<>"",(BV27+BW27)<>0),IF(CD27=1,"","要"),IF(OR(S27<>"",W27<>"",AA27<>""),"申","")) | AQ27: 控除単位 | AW27: 15 | BA27: 分 | BD27: =IF(ISERR(DAY(BG27)),1,IF(AND(DATEVALUE(BG27)>=DATEVALUE($BJ$5),DATEVALUE(BG27)<=DATEVALUE($BK$5)),0,1)) -> 0 | BE27: =$A$3 -> 2026 | BF27: =IF($B$5=$O$5,IF($B$5<$I$3,$B$5+1,$B$5),$I$3) -> 9 | BG27: =CONCATENATE(BE27,"/",BF27,"/",A27) -> 2026/9/8 | BH27: =IF(OR(COUNTIF(祝祭日!$A:$A,$BG27)>=1,OR(C27="土",C27="日",C27="",BD27=1)),0,1) -> 1 | BI27: =IF(OR(AJ27="有給休暇",AJ27="欠勤",AJ27="振替休日",AJ27="特別休暇"),1,0) -> 0 | BJ27: =IF(AJ27="振替予定休日出勤",1,0) -> 0 | BK27: =IF(AJ27="休日出勤",IF(C27="日",1,2),0) -> 0 | BL27: =IFERROR(IF(BI27=1,TIME(0,0,0),TIME(E27,G27,0)),TIME(0,0,0)) -> 0.375 | BM27: =IFERROR(IF(BI27=1,TIME(0,0,0),IF(E27>I27,TIME(I27,K27,0)+1,TIME(I27,K27,0))),TIME(0,0,0)) -> 0.73958333 | BN27: =TEXT(MAX(0,MIN($BM27,BN$7)-MAX($BL27,BN$6)),"h:mm")*24 -> 3 | BO27: =TEXT(MAX(0,MIN($BM27,BO$7)-MAX($BL27,BO$6)),"h:mm")*24 -> 1 | BP27: =TEXT(MAX(0,MIN($BM27,BP$7)-MAX($BL27,BP$6)),"h:mm")*24 -> 4.75 | BQ27: =TEXT(MAX(0,MIN($BM27,BQ$7)-MAX($BL27,BQ$6)),"h:mm")*24 -> 0 | BR27: =TEXT(MAX(0,MIN($BM27,BR$7)-MAX($BL27,BR$6)),"h:mm")*24-BQ27 -> 0 | BS27: =TEXT(MAX(0,MIN($BM27,BS$7)-MAX($BL27,BS$6)),"h:mm")*24 -> 0 | BT27: =TEXT(MAX(0,MIN($BM27,BT$7)-MAX($BL27,BT$6)),"h:mm")*24 -> 0 | BU27: =IF(OR(BH27=1,BJ27=1),BN27+BP27,0) -> 7.75 | BV27: =IF(BU27>0,IF(AJ27="遅刻（電車遅延）",0,$BH$3-BU27),0) -> 0 | BW27: =IF(AND(BU27>0,BV27=0),IF(MIN($BP$7,BM27)=BM27,($BP$7-BM27)*24,0),0) -> 0 | BX27: =MOD(ROUND(BV27+BW27,2),ROUND($BX$7,2)) -> 0 | BY27: =IF(OR(BH27=1,BJ27=1),BR27+BT27,IF(C27="日",0,BN27+BP27+BR27+BT27)) -> 0 | BZ27: =IF(OR(BH27=1,BJ27=1),BS27,0) -> 0 | CA27: =IF(AND(C27="日",BJ27=0),BN27+BP27+BR27+BT27,0) -> 0 | CB27: =IF(AND(C27="日",BJ27=0),BS27,0) -> 0 | CC27: =MOD(ROUND(BY27+BZ27+CA27+CB27,2),ROUND($CC$7,2)) -> 0 | CD27: =IF(OR(AND(AJ27="直行",AN27="直帰"),AND(AJ27="",AN27="直帰"),AND(AJ27="直行",AN27="")),1,0) -> 0 | CK27: 木
A28: 9 | C28: 水 | M28: =IF(E28="","",IF((BO28+BQ28)=0,"",(BO28+BQ28)*60)) -> 60 | O28: =IF(E28<>"",IF(BU28<>0,BU28/24,""),"") -> 0.32291667 | S28: =IF(E28<>"",IF(BY28<>0,BY28/24,""),"") | W28: =IF(E28<>"",IF(BS28<>0,BS28/24,""),"") | AA28: =IF(E28<>"",IF(CA28<>0,CA28/24,""),"") | AP28: =IF(OR(AJ28<>"",AN28<>"",(BV28+BW28)<>0),IF(CD28=1,"","要"),IF(OR(S28<>"",W28<>"",AA28<>""),"申","")) | AQ28: 休日割増適用日 | BD28: =IF(ISERR(DAY(BG28)),1,IF(AND(DATEVALUE(BG28)>=DATEVALUE($BJ$5),DATEVALUE(BG28)<=DATEVALUE($BK$5)),0,1)) -> 0 | BE28: =$A$3 -> 2026 | BF28: =IF($B$5=$O$5,IF($B$5<$I$3,$B$5+1,$B$5),$I$3) -> 9 | BG28: =CONCATENATE(BE28,"/",BF28,"/",A28) -> 2026/9/9 | BH28: =IF(OR(COUNTIF(祝祭日!$A:$A,$BG28)>=1,OR(C28="土",C28="日",C28="",BD28=1)),0,1) -> 1 | BI28: =IF(OR(AJ28="有給休暇",AJ28="欠勤",AJ28="振替休日",AJ28="特別休暇"),1,0) -> 0 | BJ28: =IF(AJ28="振替予定休日出勤",1,0) -> 0 | BK28: =IF(AJ28="休日出勤",IF(C28="日",1,2),0) -> 0 | BL28: =IFERROR(IF(BI28=1,TIME(0,0,0),TIME(E28,G28,0)),TIME(0,0,0)) -> 0.375 | BM28: =IFERROR(IF(BI28=1,TIME(0,0,0),IF(E28>I28,TIME(I28,K28,0)+1,TIME(I28,K28,0))),TIME(0,0,0)) -> 0.73958333 | BN28: =TEXT(MAX(0,MIN($BM28,BN$7)-MAX($BL28,BN$6)),"h:mm")*24 -> 3 | BO28: =TEXT(MAX(0,MIN($BM28,BO$7)-MAX($BL28,BO$6)),"h:mm")*24 -> 1 | BP28: =TEXT(MAX(0,MIN($BM28,BP$7)-MAX($BL28,BP$6)),"h:mm")*24 -> 4.75 | BQ28: =TEXT(MAX(0,MIN($BM28,BQ$7)-MAX($BL28,BQ$6)),"h:mm")*24 -> 0 | BR28: =TEXT(MAX(0,MIN($BM28,BR$7)-MAX($BL28,BR$6)),"h:mm")*24-BQ28 -> 0 | BS28: =TEXT(MAX(0,MIN($BM28,BS$7)-MAX($BL28,BS$6)),"h:mm")*24 -> 0 | BT28: =TEXT(MAX(0,MIN($BM28,BT$7)-MAX($BL28,BT$6)),"h:mm")*24 -> 0 | BU28: =IF(OR(BH28=1,BJ28=1),BN28+BP28,0) -> 7.75 | BV28: =IF(BU28>0,IF(AJ28="遅刻（電車遅延）",0,$BH$3-BU28),0) -> 0 | BW28: =IF(AND(BU28>0,BV28=0),IF(MIN($BP$7,BM28)=BM28,($BP$7-BM28)*24,0),0) -> 0 | BX28: =MOD(ROUND(BV28+BW28,2),ROUND($BX$7,2)) -> 0 | BY28: =IF(OR(BH28=1,BJ28=1),BR28+BT28,IF(C28="日",0,BN28+BP28+BR28+BT28)) -> 0 | BZ28: =IF(OR(BH28=1,BJ28=1),BS28,0) -> 0 | CA28: =IF(AND(C28="日",BJ28=0),BN28+BP28+BR28+BT28,0) -> 0 | CB28: =IF(AND(C28="日",BJ28=0),BS28,0) -> 0 | CC28: =MOD(ROUND(BY28+BZ28+CA28+CB28,2),ROUND($CC$7,2)) -> 0 | CD28: =IF(OR(AND(AJ28="直行",AN28="直帰"),AND(AJ28="",AN28="直帰"),AND(AJ28="直行",AN28="")),1,0) -> 0 | CK28: 金
A29: 10 | C29: 木 | M29: =IF(E29="","",IF((BO29+BQ29)=0,"",(BO29+BQ29)*60)) -> 60 | O29: =IF(E29<>"",IF(BU29<>0,BU29/24,""),"") -> 0.32291667 | S29: =IF(E29<>"",IF(BY29<>0,BY29/24,""),"") | W29: =IF(E29<>"",IF(BS29<>0,BS29/24,""),"") | AA29: =IF(E29<>"",IF(CA29<>0,CA29/24,""),"") | AP29: =IF(OR(AJ29<>"",AN29<>"",(BV29+BW29)<>0),IF(CD29=1,"","要"),IF(OR(S29<>"",W29<>"",AA29<>""),"申","")) | BD29: =IF(ISERR(DAY(BG29)),1,IF(AND(DATEVALUE(BG29)>=DATEVALUE($BJ$5),DATEVALUE(BG29)<=DATEVALUE($BK$5)),0,1)) -> 0 | BE29: =$A$3 -> 2026 | BF29: =IF($B$5=$O$5,IF($B$5<$I$3,$B$5+1,$B$5),$I$3) -> 9 | BG29: =CONCATENATE(BE29,"/",BF29,"/",A29) -> 2026/9/10 | BH29: =IF(OR(COUNTIF(祝祭日!$A:$A,$BG29)>=1,OR(C29="土",C29="日",C29="",BD29=1)),0,1) -> 1 | BI29: =IF(OR(AJ29="有給休暇",AJ29="欠勤",AJ29="振替休日",AJ29="特別休暇"),1,0) -> 0 | BJ29: =IF(AJ29="振替予定休日出勤",1,0) -> 0 | BK29: =IF(AJ29="休日出勤",IF(C29="日",1,2),0) -> 0 | BL29: =IFERROR(IF(BI29=1,TIME(0,0,0),TIME(E29,G29,0)),TIME(0,0,0)) -> 0.375 | BM29: =IFERROR(IF(BI29=1,TIME(0,0,0),IF(E29>I29,TIME(I29,K29,0)+1,TIME(I29,K29,0))),TIME(0,0,0)) -> 0.73958333 | BN29: =TEXT(MAX(0,MIN($BM29,BN$7)-MAX($BL29,BN$6)),"h:mm")*24 -> 3 | BO29: =TEXT(MAX(0,MIN($BM29,BO$7)-MAX($BL29,BO$6)),"h:mm")*24 -> 1 | BP29: =TEXT(MAX(0,MIN($BM29,BP$7)-MAX($BL29,BP$6)),"h:mm")*24 -> 4.75 | BQ29: =TEXT(MAX(0,MIN($BM29,BQ$7)-MAX($BL29,BQ$6)),"h:mm")*24 -> 0 | BR29: =TEXT(MAX(0,MIN($BM29,BR$7)-MAX($BL29,BR$6)),"h:mm")*24-BQ29 -> 0 | BS29: =TEXT(MAX(0,MIN($BM29,BS$7)-MAX($BL29,BS$6)),"h:mm")*24 -> 0 | BT29: =TEXT(MAX(0,MIN($BM29,BT$7)-MAX($BL29,BT$6)),"h:mm")*24 -> 0 | BU29: =IF(OR(BH29=1,BJ29=1),BN29+BP29,0) -> 7.75 | BV29: =IF(BU29>0,IF(AJ29="遅刻（電車遅延）",0,$BH$3-BU29),0) -> 0 | BW29: =IF(AND(BU29>0,BV29=0),IF(MIN($BP$7,BM29)=BM29,($BP$7-BM29)*24,0),0) -> 0 | BX29: =MOD(ROUND(BV29+BW29,2),ROUND($BX$7,2)) -> 0 | BY29: =IF(OR(BH29=1,BJ29=1),BR29+BT29,IF(C29="日",0,BN29+BP29+BR29+BT29)) -> 0 | BZ29: =IF(OR(BH29=1,BJ29=1),BS29,0) -> 0 | CA29: =IF(AND(C29="日",BJ29=0),BN29+BP29+BR29+BT29,0) -> 0 | CB29: =IF(AND(C29="日",BJ29=0),BS29,0) -> 0 | CC29: =MOD(ROUND(BY29+BZ29+CA29+CB29,2),ROUND($CC$7,2)) -> 0 | CD29: =IF(OR(AND(AJ29="直行",AN29="直帰"),AND(AJ29="",AN29="直帰"),AND(AJ29="直行",AN29="")),1,0) -> 0 | CK29: 土
A30: 11 | C30: 金 | M30: =IF(E30="","",IF((BO30+BQ30)=0,"",(BO30+BQ30)*60)) -> 60 | O30: =IF(E30<>"",IF(BU30<>0,BU30/24,""),"") -> 0.32291667 | AP30: =IF(OR(AJ30<>"",AN30<>"",(BV30+BW30)<>0),IF(CD30=1,"","要"),IF(OR(S30<>"",W30<>"",AA30<>""),"申","")) | AQ30: 日曜日 | BD30: =IF(ISERR(DAY(BG30)),1,IF(AND(DATEVALUE(BG30)>=DATEVALUE($BJ$5),DATEVALUE(BG30)<=DATEVALUE($BK$5)),0,1)) -> 0 | BE30: =$A$3 -> 2026 | BF30: =IF($B$5=$O$5,IF($B$5<$I$3,$B$5+1,$B$5),$I$3) -> 9 | BG30: =CONCATENATE(BE30,"/",BF30,"/",A30) -> 2026/9/11 | BH30: =IF(OR(COUNTIF(祝祭日!$A:$A,$BG30)>=1,OR(C30="土",C30="日",C30="",BD30=1)),0,1) -> 1 | BI30: =IF(OR(AJ30="有給休暇",AJ30="欠勤",AJ30="振替休日",AJ30="特別休暇"),1,0) -> 0 | BJ30: =IF(AJ30="振替予定休日出勤",1,0) -> 0 | BK30: =IF(AJ30="休日出勤",IF(C30="日",1,2),0) -> 0 | BL30: =IFERROR(IF(BI30=1,TIME(0,0,0),TIME(E30,G30,0)),TIME(0,0,0)) -> 0.375 | BM30: =IFERROR(IF(BI30=1,TIME(0,0,0),IF(E30>I30,TIME(I30,K30,0)+1,TIME(I30,K30,0))),TIME(0,0,0)) -> 0.73958333 | BN30: =TEXT(MAX(0,MIN($BM30,BN$7)-MAX($BL30,BN$6)),"h:mm")*24 -> 3 | BO30: =TEXT(MAX(0,MIN($BM30,BO$7)-MAX($BL30,BO$6)),"h:mm")*24 -> 1 | BP30: =TEXT(MAX(0,MIN($BM30,BP$7)-MAX($BL30,BP$6)),"h:mm")*24 -> 4.75 | BQ30: =TEXT(MAX(0,MIN($BM30,BQ$7)-MAX($BL30,BQ$6)),"h:mm")*24 -> 0 | BR30: =TEXT(MAX(0,MIN($BM30,BR$7)-MAX($BL30,BR$6)),"h:mm")*24-BQ30 -> 0 | BS30: =TEXT(MAX(0,MIN($BM30,BS$7)-MAX($BL30,BS$6)),"h:mm")*24 -> 0 | BT30: =TEXT(MAX(0,MIN($BM30,BT$7)-MAX($BL30,BT$6)),"h:mm")*24 -> 0 | BU30: =IF(OR(BH30=1,BJ30=1),BN30+BP30,0) -> 7.75 | BV30: =IF(BU30>0,IF(AJ30="遅刻（電車遅延）",0,$BH$3-BU30),0) -> 0 | BW30: =IF(AND(BU30>0,BV30=0),IF(MIN($BP$7,BM30)=BM30,($BP$7-BM30)*24,0),0) -> 0 | BX30: =MOD(ROUND(BV30+BW30,2),ROUND($BX$7,2)) -> 0 | BY30: =IF(OR(BH30=1,BJ30=1),BR30+BT30,IF(C30="日",0,BN30+BP30+BR30+BT30)) -> 0 | BZ30: =IF(OR(BH30=1,BJ30=1),BS30,0) -> 0 | CA30: =IF(AND(C30="日",BJ30=0),BN30+BP30+BR30+BT30,0) -> 0 | CB30: =IF(AND(C30="日",BJ30=0),BS30,0) -> 0 | CC30: =MOD(ROUND(BY30+BZ30+CA30+CB30,2),ROUND($CC$7,2)) -> 0 | CD30: =IF(OR(AND(AJ30="直行",AN30="直帰"),AND(AJ30="",AN30="直帰"),AND(AJ30="直行",AN30="")),1,0) -> 0 | CK30: 日
A31: 12 | C31: 土 | AP31: =IF(OR(AJ31<>"",AN31<>"",(BV31+BW31)<>0),IF(CD31=1,"","要"),IF(OR(S31<>"",W31<>"",AA31<>""),"申","")) | BD31: =IF(ISERR(DAY(BG31)),1,IF(AND(DATEVALUE(BG31)>=DATEVALUE($BJ$5),DATEVALUE(BG31)<=DATEVALUE($BK$5)),0,1)) -> 0 | BE31: =$A$3 -> 2026 | BF31: =IF($B$5=$O$5,IF($B$5<$I$3,$B$5+1,$B$5),$I$3) -> 9 | BG31: =CONCATENATE(BE31,"/",BF31,"/",A31) -> 2026/9/12 | BH31: =IF(OR(COUNTIF(祝祭日!$A:$A,$BG31)>=1,OR(C31="土",C31="日",C31="",BD31=1)),0,1) -> 0 | BI31: =IF(OR(AJ31="有給休暇",AJ31="欠勤",AJ31="振替休日",AJ31="特別休暇"),1,0) -> 0 | BJ31: =IF(AJ31="振替予定休日出勤",1,0) -> 0 | BK31: =IF(AJ31="休日出勤",IF(C31="日",1,2),0) -> 0 | BL31: =IFERROR(IF(BI31=1,TIME(0,0,0),TIME(E31,G31,0)),TIME(0,0,0)) -> 0 | BM31: =IFERROR(IF(BI31=1,TIME(0,0,0),IF(E31>I31,TIME(I31,K31,0)+1,TIME(I31,K31,0))),TIME(0,0,0)) -> 0 | BN31: =TEXT(MAX(0,MIN($BM31,BN$7)-MAX($BL31,BN$6)),"h:mm")*24 -> 0 | BO31: =TEXT(MAX(0,MIN($BM31,BO$7)-MAX($BL31,BO$6)),"h:mm")*24 -> 0 | BP31: =TEXT(MAX(0,MIN($BM31,BP$7)-MAX($BL31,BP$6)),"h:mm")*24 -> 0 | BQ31: =TEXT(MAX(0,MIN($BM31,BQ$7)-MAX($BL31,BQ$6)),"h:mm")*24 -> 0 | BR31: =TEXT(MAX(0,MIN($BM31,BR$7)-MAX($BL31,BR$6)),"h:mm")*24-BQ31 -> 0 | BS31: =TEXT(MAX(0,MIN($BM31,BS$7)-MAX($BL31,BS$6)),"h:mm")*24 -> 0 | BT31: =TEXT(MAX(0,MIN($BM31,BT$7)-MAX($BL31,BT$6)),"h:mm")*24 -> 0 | BU31: =IF(OR(BH31=1,BJ31=1),BN31+BP31,0) -> 0 | BV31: =IF(BU31>0,IF(AJ31="遅刻（電車遅延）",0,$BH$3-BU31),0) -> 0 | BW31: =IF(AND(BU31>0,BV31=0),IF(MIN($BP$7,BM31)=BM31,($BP$7-BM31)*24,0),0) -> 0 | BX31: =MOD(ROUND(BV31+BW31,2),ROUND($BX$7,2)) -> 0 | BY31: =IF(OR(BH31=1,BJ31=1),BR31+BT31,IF(C31="日",0,BN31+BP31+BR31+BT31)) -> 0 | BZ31: =IF(OR(BH31=1,BJ31=1),BS31,0) -> 0 | CA31: =IF(AND(C31="日",BJ31=0),BN31+BP31+BR31+BT31,0) -> 0 | CB31: =IF(AND(C31="日",BJ31=0),BS31,0) -> 0 | CC31: =MOD(ROUND(BY31+BZ31+CA31+CB31,2),ROUND($CC$7,2)) -> 0 | CD31: =IF(OR(AND(AJ31="直行",AN31="直帰"),AND(AJ31="",AN31="直帰"),AND(AJ31="直行",AN31="")),1,0) -> 0 | CK31: 月
A32: 13 | C32: 日 | AP32: =IF(OR(AJ32<>"",AN32<>"",(BV32+BW32)<>0),IF(CD32=1,"","要"),IF(OR(S32<>"",W32<>"",AA32<>""),"申","")) | BD32: =IF(ISERR(DAY(BG32)),1,IF(AND(DATEVALUE(BG32)>=DATEVALUE($BJ$5),DATEVALUE(BG32)<=DATEVALUE($BK$5)),0,1)) -> 0 | BE32: =$A$3 -> 2026 | BF32: =IF($B$5=$O$5,IF($B$5<$I$3,$B$5+1,$B$5),$I$3) -> 9 | BG32: =CONCATENATE(BE32,"/",BF32,"/",A32) -> 2026/9/13 | BH32: =IF(OR(COUNTIF(祝祭日!$A:$A,$BG32)>=1,OR(C32="土",C32="日",C32="",BD32=1)),0,1) -> 0 | BI32: =IF(OR(AJ32="有給休暇",AJ32="欠勤",AJ32="振替休日",AJ32="特別休暇"),1,0) -> 0 | BJ32: =IF(AJ32="振替予定休日出勤",1,0) -> 0 | BK32: =IF(AJ32="休日出勤",IF(C32="日",1,2),0) -> 0 | BL32: =IFERROR(IF(BI32=1,TIME(0,0,0),TIME(E32,G32,0)),TIME(0,0,0)) -> 0 | BM32: =IFERROR(IF(BI32=1,TIME(0,0,0),IF(E32>I32,TIME(I32,K32,0)+1,TIME(I32,K32,0))),TIME(0,0,0)) -> 0 | BN32: =TEXT(MAX(0,MIN($BM32,BN$7)-MAX($BL32,BN$6)),"h:mm")*24 -> 0 | BO32: =TEXT(MAX(0,MIN($BM32,BO$7)-MAX($BL32,BO$6)),"h:mm")*24 -> 0 | BP32: =TEXT(MAX(0,MIN($BM32,BP$7)-MAX($BL32,BP$6)),"h:mm")*24 -> 0 | BQ32: =TEXT(MAX(0,MIN($BM32,BQ$7)-MAX($BL32,BQ$6)),"h:mm")*24 -> 0 | BR32: =TEXT(MAX(0,MIN($BM32,BR$7)-MAX($BL32,BR$6)),"h:mm")*24-BQ32 -> 0 | BS32: =TEXT(MAX(0,MIN($BM32,BS$7)-MAX($BL32,BS$6)),"h:mm")*24 -> 0 | BT32: =TEXT(MAX(0,MIN($BM32,BT$7)-MAX($BL32,BT$6)),"h:mm")*24 -> 0 | BU32: =IF(OR(BH32=1,BJ32=1),BN32+BP32,0) -> 0 | BV32: =IF(BU32>0,IF(AJ32="遅刻（電車遅延）",0,$BH$3-BU32),0) -> 0 | BW32: =IF(AND(BU32>0,BV32=0),IF(MIN($BP$7,BM32)=BM32,($BP$7-BM32)*24,0),0) -> 0 | BX32: =MOD(ROUND(BV32+BW32,2),ROUND($BX$7,2)) -> 0 | BY32: =IF(OR(BH32=1,BJ32=1),BR32+BT32,IF(C32="日",0,BN32+BP32+BR32+BT32)) -> 0 | BZ32: =IF(OR(BH32=1,BJ32=1),BS32,0) -> 0 | CA32: =IF(AND(C32="日",BJ32=0),BN32+BP32+BR32+BT32,0) -> 0 | CB32: =IF(AND(C32="日",BJ32=0),BS32,0) -> 0 | CC32: =MOD(ROUND(BY32+BZ32+CA32+CB32,2),ROUND($CC$7,2)) -> 0 | CD32: =IF(OR(AND(AJ32="直行",AN32="直帰"),AND(AJ32="",AN32="直帰"),AND(AJ32="直行",AN32="")),1,0) -> 0 | CK32: 火
A33: 14 | AP33: =IF(OR(AJ33<>"",AN33<>"",(BV33+BW33)<>0),IF(CD33=1,"","要"),IF(OR(S33<>"",W33<>"",AA33<>""),"申","")) | BD33: =IF(ISERR(DAY(BG33)),1,IF(AND(DATEVALUE(BG33)>=DATEVALUE($BJ$5),DATEVALUE(BG33)<=DATEVALUE($BK$5)),0,1)) -> 0 | BE33: =$A$3 -> 2026 | BF33: =IF($B$5=$O$5,IF($B$5<$I$3,$B$5+1,$B$5),$I$3) -> 9 | BG33: =CONCATENATE(BE33,"/",BF33,"/",A33) -> 2026/9/14 | BH33: =IF(OR(COUNTIF(祝祭日!$A:$A,$BG33)>=1,OR(C33="土",C33="日",C33="",BD33=1)),0,1) -> 0 | BI33: =IF(OR(AJ33="有給休暇",AJ33="欠勤",AJ33="振替休日",AJ33="特別休暇"),1,0) -> 0 | BJ33: =IF(AJ33="振替予定休日出勤",1,0) -> 0 | BK33: =IF(AJ33="休日出勤",IF(C33="日",1,2),0) -> 0 | BL33: =IFERROR(IF(BI33=1,TIME(0,0,0),TIME(E33,G33,0)),TIME(0,0,0)) -> 0 | BM33: =IFERROR(IF(BI33=1,TIME(0,0,0),IF(E33>I33,TIME(I33,K33,0)+1,TIME(I33,K33,0))),TIME(0,0,0)) -> 0 | BN33: =TEXT(MAX(0,MIN($BM33,BN$7)-MAX($BL33,BN$6)),"h:mm")*24 -> 0 | BO33: =TEXT(MAX(0,MIN($BM33,BO$7)-MAX($BL33,BO$6)),"h:mm")*24 -> 0 | BP33: =TEXT(MAX(0,MIN($BM33,BP$7)-MAX($BL33,BP$6)),"h:mm")*24 -> 0 | BQ33: =TEXT(MAX(0,MIN($BM33,BQ$7)-MAX($BL33,BQ$6)),"h:mm")*24 -> 0 | BR33: =TEXT(MAX(0,MIN($BM33,BR$7)-MAX($BL33,BR$6)),"h:mm")*24-BQ33 -> 0 | BS33: =TEXT(MAX(0,MIN($BM33,BS$7)-MAX($BL33,BS$6)),"h:mm")*24 -> 0 | BT33: =TEXT(MAX(0,MIN($BM33,BT$7)-MAX($BL33,BT$6)),"h:mm")*24 -> 0 | BU33: =IF(OR(BH33=1,BJ33=1),BN33+BP33,0) -> 0 | BV33: =IF(BU33>0,IF(AJ33="遅刻（電車遅延）",0,$BH$3-BU33),0) -> 0 | BW33: =IF(AND(BU33>0,BV33=0),IF(MIN($BP$7,BM33)=BM33,($BP$7-BM33)*24,0),0) -> 0 | BX33: =MOD(ROUND(BV33+BW33,2),ROUND($BX$7,2)) -> 0 | BY33: =IF(OR(BH33=1,BJ33=1),BR33+BT33,IF(C33="日",0,BN33+BP33+BR33+BT33)) -> 0 | BZ33: =IF(OR(BH33=1,BJ33=1),BS33,0) -> 0 | CA33: =IF(AND(C33="日",BJ33=0),BN33+BP33+BR33+BT33,0) -> 0 | CB33: =IF(AND(C33="日",BJ33=0),BS33,0) -> 0 | CC33: =MOD(ROUND(BY33+BZ33+CA33+CB33,2),ROUND($CC$7,2)) -> 0 | CD33: =IF(OR(AND(AJ33="直行",AN33="直帰"),AND(AJ33="",AN33="直帰"),AND(AJ33="直行",AN33="")),1,0) -> 0 | CK33: 水
A34: 15 | M34: =IF(E34="","",IF((BO34+BQ34)=0,"",(BO34+BQ34)*60)) | O34: =IF(E34<>"",IF(BU34<>0,BU34/24,""),"") | S34: =IF(E34<>"",IF(BY34<>0,BY34/24,""),"") | W34: =IF(E34<>"",IF(BS34<>0,BS34/24,""),"") | AA34: =IF(E34<>"",IF(CA34<>0,CA34/24,""),"") | AP34: =IF(OR(AJ34<>"",AN34<>"",(BV34+BW34)<>0),IF(CD34=1,"","要"),IF(OR(S34<>"",W34<>"",AA34<>""),"申","")) | BD34: =IF(ISERR(DAY(BG34)),1,IF(AND(DATEVALUE(BG34)>=DATEVALUE($BJ$5),DATEVALUE(BG34)<=DATEVALUE($BK$5)),0,1)) -> 0 | BE34: =$A$3 -> 2026 | BF34: =IF($B$5=$O$5,IF($B$5<$I$3,$B$5+1,$B$5),$I$3) -> 9 | BG34: =CONCATENATE(BE34,"/",BF34,"/",A34) -> 2026/9/15 | BH34: =IF(OR(COUNTIF(祝祭日!$A:$A,$BG34)>=1,OR(C34="土",C34="日",C34="",BD34=1)),0,1) -> 0 | BI34: =IF(OR(AJ34="有給休暇",AJ34="欠勤",AJ34="振替休日",AJ34="特別休暇"),1,0) -> 0 | BJ34: =IF(AJ34="振替予定休日出勤",1,0) -> 0 | BK34: =IF(AJ34="休日出勤",IF(C34="日",1,2),0) -> 0 | BL34: =IFERROR(IF(BI34=1,TIME(0,0,0),TIME(E34,G34,0)),TIME(0,0,0)) -> 0 | BM34: =IFERROR(IF(BI34=1,TIME(0,0,0),IF(E34>I34,TIME(I34,K34,0)+1,TIME(I34,K34,0))),TIME(0,0,0)) -> 0 | BN34: =TEXT(MAX(0,MIN($BM34,BN$7)-MAX($BL34,BN$6)),"h:mm")*24 -> 0 | BO34: =TEXT(MAX(0,MIN($BM34,BO$7)-MAX($BL34,BO$6)),"h:mm")*24 -> 0 | BP34: =TEXT(MAX(0,MIN($BM34,BP$7)-MAX($BL34,BP$6)),"h:mm")*24 -> 0 | BQ34: =TEXT(MAX(0,MIN($BM34,BQ$7)-MAX($BL34,BQ$6)),"h:mm")*24 -> 0 | BR34: =TEXT(MAX(0,MIN($BM34,BR$7)-MAX($BL34,BR$6)),"h:mm")*24-BQ34 -> 0 | BS34: =TEXT(MAX(0,MIN($BM34,BS$7)-MAX($BL34,BS$6)),"h:mm")*24 -> 0 | BT34: =TEXT(MAX(0,MIN($BM34,BT$7)-MAX($BL34,BT$6)),"h:mm")*24 -> 0 | BU34: =IF(OR(BH34=1,BJ34=1),BN34+BP34,0) -> 0 | BV34: =IF(BU34>0,IF(AJ34="遅刻（電車遅延）",0,$BH$3-BU34),0) -> 0 | BW34: =IF(AND(BU34>0,BV34=0),IF(MIN($BP$7,BM34)=BM34,($BP$7-BM34)*24,0),0) -> 0 | BX34: =MOD(ROUND(BV34+BW34,2),ROUND($BX$7,2)) -> 0 | BY34: =IF(OR(BH34=1,BJ34=1),BR34+BT34,IF(C34="日",0,BN34+BP34+BR34+BT34)) -> 0 | BZ34: =IF(OR(BH34=1,BJ34=1),BS34,0) -> 0 | CA34: =IF(AND(C34="日",BJ34=0),BN34+BP34+BR34+BT34,0) -> 0 | CB34: =IF(AND(C34="日",BJ34=0),BS34,0) -> 0 | CC34: =MOD(ROUND(BY34+BZ34+CA34+CB34,2),ROUND($CC$7,2)) -> 0 | CD34: =IF(OR(AND(AJ34="直行",AN34="直帰"),AND(AJ34="",AN34="直帰"),AND(AJ34="直行",AN34="")),1,0) -> 0 | CK34: 木
A35: 16 | M35: =IF(E35="","",IF((BO35+BQ35)=0,"",(BO35+BQ35)*60)) | O35: =IF(E35<>"",IF(BU35<>0,BU35/24,""),"") | S35: =IF(E35<>"",IF(BY35<>0,BY35/24,""),"") | W35: =IF(E35<>"",IF(BS35<>0,BS35/24,""),"") | AA35: =IF(E35<>"",IF(CA35<>0,CA35/24,""),"") | AP35: =IF(OR(AJ35<>"",AN35<>"",(BV35+BW35)<>0),IF(CD35=1,"","要"),IF(OR(S35<>"",W35<>"",AA35<>""),"申","")) | BD35: =IF(ISERR(DAY(BG35)),1,IF(AND(DATEVALUE(BG35)>=DATEVALUE($BJ$5),DATEVALUE(BG35)<=DATEVALUE($BK$5)),0,1)) -> 0 | BE35: =$A$3 -> 2026 | BF35: =IF($B$5=$O$5,IF($B$5<$I$3,$B$5+1,$B$5),$I$3) -> 9 | BG35: =CONCATENATE(BE35,"/",BF35,"/",A35) -> 2026/9/16 | BH35: =IF(OR(COUNTIF(祝祭日!$A:$A,$BG35)>=1,OR(C35="土",C35="日",C35="",BD35=1)),0,1) -> 0 | BI35: =IF(OR(AJ35="有給休暇",AJ35="欠勤",AJ35="振替休日",AJ35="特別休暇"),1,0) -> 0 | BJ35: =IF(AJ35="振替予定休日出勤",1,0) -> 0 | BK35: =IF(AJ35="休日出勤",IF(C35="日",1,2),0) -> 0 | BL35: =IFERROR(IF(BI35=1,TIME(0,0,0),TIME(E35,G35,0)),TIME(0,0,0)) -> 0 | BM35: =IFERROR(IF(BI35=1,TIME(0,0,0),IF(E35>I35,TIME(I35,K35,0)+1,TIME(I35,K35,0))),TIME(0,0,0)) -> 0 | BN35: =TEXT(MAX(0,MIN($BM35,BN$7)-MAX($BL35,BN$6)),"h:mm")*24 -> 0 | BO35: =TEXT(MAX(0,MIN($BM35,BO$7)-MAX($BL35,BO$6)),"h:mm")*24 -> 0 | BP35: =TEXT(MAX(0,MIN($BM35,BP$7)-MAX($BL35,BP$6)),"h:mm")*24 -> 0 | BQ35: =TEXT(MAX(0,MIN($BM35,BQ$7)-MAX($BL35,BQ$6)),"h:mm")*24 -> 0 | BR35: =TEXT(MAX(0,MIN($BM35,BR$7)-MAX($BL35,BR$6)),"h:mm")*24-BQ35 -> 0 | BS35: =TEXT(MAX(0,MIN($BM35,BS$7)-MAX($BL35,BS$6)),"h:mm")*24 -> 0 | BT35: =TEXT(MAX(0,MIN($BM35,BT$7)-MAX($BL35,BT$6)),"h:mm")*24 -> 0 | BU35: =IF(OR(BH35=1,BJ35=1),BN35+BP35,0) -> 0 | BV35: =IF(BU35>0,IF(AJ35="遅刻（電車遅延）",0,$BH$3-BU35),0) -> 0 | BW35: =IF(AND(BU35>0,BV35=0),IF(MIN($BP$7,BM35)=BM35,($BP$7-BM35)*24,0),0) -> 0 | BX35: =MOD(ROUND(BV35+BW35,2),ROUND($BX$7,2)) -> 0 | BY35: =IF(OR(BH35=1,BJ35=1),BR35+BT35,IF(C35="日",0,BN35+BP35+BR35+BT35)) -> 0 | BZ35: =IF(OR(BH35=1,BJ35=1),BS35,0) -> 0 | CA35: =IF(AND(C35="日",BJ35=0),BN35+BP35+BR35+BT35,0) -> 0 | CB35: =IF(AND(C35="日",BJ35=0),BS35,0) -> 0 | CC35: =MOD(ROUND(BY35+BZ35+CA35+CB35,2),ROUND($CC$7,2)) -> 0 | CD35: =IF(OR(AND(AJ35="直行",AN35="直帰"),AND(AJ35="",AN35="直帰"),AND(AJ35="直行",AN35="")),1,0) -> 0 | CK35: 金
